 Network jojodev_default  Creating
 Network jojodev_default  Created
 Container jojodev-db-1  Creating
 Container jojodev-db-1  Created
 Container jojodev-api02-1  Creating
 Container jojodev-api01-1  Creating
 Container jojodev-api02-1  Created
 Container jojodev-api01-1  Created
 Container jojodev-nginx-1  Creating
 Container jojodev-nginx-1  Created
Attaching to api01-1, api02-1, db-1, nginx-1
db-1     | 2024-02-12 16:52:49+00:00 [Note] [Entrypoint]: Entrypoint script for MySQL Server 8.3.0-1.el8 started.
api01-1  | wait-for-it: waiting 15 seconds for db:3306
api02-1  | wait-for-it: waiting 15 seconds for db:3306
nginx-1  | /docker-entrypoint.sh: /docker-entrypoint.d/ is not empty, will attempt to perform configuration
nginx-1  | /docker-entrypoint.sh: Looking for shell scripts in /docker-entrypoint.d/
nginx-1  | /docker-entrypoint.sh: Launching /docker-entrypoint.d/10-listen-on-ipv6-by-default.sh
nginx-1  | 10-listen-on-ipv6-by-default.sh: info: Getting the checksum of /etc/nginx/conf.d/default.conf
nginx-1  | 10-listen-on-ipv6-by-default.sh: info: Enabled listen on IPv6 in /etc/nginx/conf.d/default.conf
nginx-1  | /docker-entrypoint.sh: Sourcing /docker-entrypoint.d/15-local-resolvers.envsh
nginx-1  | /docker-entrypoint.sh: Launching /docker-entrypoint.d/20-envsubst-on-templates.sh
nginx-1  | /docker-entrypoint.sh: Launching /docker-entrypoint.d/30-tune-worker-processes.sh
nginx-1  | /docker-entrypoint.sh: Configuration complete; ready for start up
nginx-1  | 2024/02/12 16:52:50 [error] 29#29: *1 connect() failed (111: Connection refused) while connecting to upstream, client: 172.26.0.1, server: , request: "GET /clientes/1/extrato HTTP/1.1", upstream: "http://172.26.0.3:5000/clientes/1/extrato", host: "localhost:9999"
nginx-1  | 2024/02/12 16:52:50 [error] 29#29: *1 connect() failed (111: Connection refused) while connecting to upstream, client: 172.26.0.1, server: , request: "GET /clientes/1/extrato HTTP/1.1", upstream: "http://172.26.0.4:5000/clientes/1/extrato", host: "localhost:9999"
db-1     | 2024-02-12 16:52:51+00:00 [Note] [Entrypoint]: Switching to dedicated user 'mysql'
db-1     | 2024-02-12 16:52:51+00:00 [Note] [Entrypoint]: Entrypoint script for MySQL Server 8.3.0-1.el8 started.
nginx-1  | 2024/02/12 16:52:52 [error] 29#29: *4 no live upstreams while connecting to upstream, client: 172.26.0.1, server: , request: "GET /clientes/1/extrato HTTP/1.1", upstream: "http://api/clientes/1/extrato", host: "localhost:9999"
db-1     | 2024-02-12 16:52:53+00:00 [Note] [Entrypoint]: Initializing database files
db-1     | 2024-02-12T16:52:53.295559Z 0 [System] [MY-015017] [Server] MySQL Server Initialization - start.
db-1     | 2024-02-12T16:52:53.297634Z 0 [System] [MY-013169] [Server] /usr/sbin/mysqld (mysqld 8.3.0) initializing of server in progress as process 79
db-1     | 2024-02-12T16:52:53.419512Z 1 [System] [MY-013576] [InnoDB] InnoDB initialization has started.
nginx-1  | 2024/02/12 16:52:54 [error] 29#29: *5 no live upstreams while connecting to upstream, client: 172.26.0.1, server: , request: "GET /clientes/1/extrato HTTP/1.1", upstream: "http://api/clientes/1/extrato", host: "localhost:9999"
db-1     | 2024-02-12T16:52:55.955414Z 1 [System] [MY-013577] [InnoDB] InnoDB initialization has ended.
nginx-1  | 2024/02/12 16:52:56 [error] 29#29: *6 no live upstreams while connecting to upstream, client: 172.26.0.1, server: , request: "GET /clientes/1/extrato HTTP/1.1", upstream: "http://api/clientes/1/extrato", host: "localhost:9999"
nginx-1  | 2024/02/12 16:52:58 [error] 29#29: *7 no live upstreams while connecting to upstream, client: 172.26.0.1, server: , request: "GET /clientes/1/extrato HTTP/1.1", upstream: "http://api/clientes/1/extrato", host: "localhost:9999"
nginx-1  | 2024/02/12 16:53:00 [error] 29#29: *8 no live upstreams while connecting to upstream, client: 172.26.0.1, server: , request: "GET /clientes/1/extrato HTTP/1.1", upstream: "http://api/clientes/1/extrato", host: "localhost:9999"
nginx-1  | 2024/02/12 16:53:02 [error] 29#29: *9 connect() failed (111: Connection refused) while connecting to upstream, client: 172.26.0.1, server: , request: "GET /clientes/1/extrato HTTP/1.1", upstream: "http://172.26.0.4:5000/clientes/1/extrato", host: "localhost:9999"
nginx-1  | 2024/02/12 16:53:02 [error] 29#29: *9 connect() failed (111: Connection refused) while connecting to upstream, client: 172.26.0.1, server: , request: "GET /clientes/1/extrato HTTP/1.1", upstream: "http://172.26.0.3:5000/clientes/1/extrato", host: "localhost:9999"
db-1     | 2024-02-12T16:53:03.717054Z 6 [Warning] [MY-010453] [Server] root@localhost is created with an empty password ! Please consider switching off the --initialize-insecure option.
nginx-1  | 2024/02/12 16:53:04 [error] 29#29: *12 no live upstreams while connecting to upstream, client: 172.26.0.1, server: , request: "GET /clientes/1/extrato HTTP/1.1", upstream: "http://api/clientes/1/extrato", host: "localhost:9999"
api01-1  | wait-for-it: timeout occurred after waiting 15 seconds for db:3306
api02-1  | wait-for-it: timeout occurred after waiting 15 seconds for db:3306
api02-1  |  * Serving Flask app 'main'
api02-1  |  * Debug mode: off
api01-1  |  * Serving Flask app 'main'
api01-1  |  * Debug mode: off
api01-1  | [31m[1mWARNING: This is a development server. Do not use it in a production deployment. Use a production WSGI server instead.[0m
api01-1  |  * Running on all addresses (0.0.0.0)
api01-1  |  * Running on http://127.0.0.1:5000
api01-1  |  * Running on http://172.26.0.3:5000
api01-1  | [33mPress CTRL+C to quit[0m
api02-1  | [31m[1mWARNING: This is a development server. Do not use it in a production deployment. Use a production WSGI server instead.[0m
api02-1  |  * Running on all addresses (0.0.0.0)
api02-1  |  * Running on http://127.0.0.1:5000
api02-1  |  * Running on http://172.26.0.4:5000
api02-1  | [33mPress CTRL+C to quit[0m
nginx-1  | 2024/02/12 16:53:06 [error] 29#29: *13 no live upstreams while connecting to upstream, client: 172.26.0.1, server: , request: "GET /clientes/1/extrato HTTP/1.1", upstream: "http://api/clientes/1/extrato", host: "localhost:9999"
nginx-1  | 2024/02/12 16:53:08 [error] 29#29: *14 no live upstreams while connecting to upstream, client: 172.26.0.1, server: , request: "GET /clientes/1/extrato HTTP/1.1", upstream: "http://api/clientes/1/extrato", host: "localhost:9999"
nginx-1  | 2024/02/12 16:53:10 [error] 29#29: *15 no live upstreams while connecting to upstream, client: 172.26.0.1, server: , request: "GET /clientes/1/extrato HTTP/1.1", upstream: "http://api/clientes/1/extrato", host: "localhost:9999"
nginx-1  | 2024/02/12 16:53:12 [error] 29#29: *16 no live upstreams while connecting to upstream, client: 172.26.0.1, server: , request: "GET /clientes/1/extrato HTTP/1.1", upstream: "http://api/clientes/1/extrato", host: "localhost:9999"
api02-1  | [2024-02-12 16:53:14,575] ERROR in app: Exception on /clientes/1/extrato [GET]
api02-1  | Traceback (most recent call last):
api02-1  |   File "/usr/local/lib/python3.9/site-packages/sqlalchemy/engine/base.py", line 145, in __init__
api02-1  |     self._dbapi_connection = engine.raw_connection()
api02-1  |   File "/usr/local/lib/python3.9/site-packages/sqlalchemy/engine/base.py", line 3293, in raw_connection
api02-1  |     return self.pool.connect()
api02-1  |   File "/usr/local/lib/python3.9/site-packages/sqlalchemy/pool/base.py", line 452, in connect
api02-1  |     return _ConnectionFairy._checkout(self)
api02-1  |   File "/usr/local/lib/python3.9/site-packages/sqlalchemy/pool/base.py", line 1269, in _checkout
api02-1  |     fairy = _ConnectionRecord.checkout(pool)
api02-1  |   File "/usr/local/lib/python3.9/site-packages/sqlalchemy/pool/base.py", line 716, in checkout
api02-1  |     rec = pool._do_get()
api02-1  |   File "/usr/local/lib/python3.9/site-packages/sqlalchemy/pool/impl.py", line 170, in _do_get
api02-1  |     self._dec_overflow()
api02-1  |   File "/usr/local/lib/python3.9/site-packages/sqlalchemy/util/langhelpers.py", line 146, in __exit__
api02-1  |     raise exc_value.with_traceback(exc_tb)
api02-1  |   File "/usr/local/lib/python3.9/site-packages/sqlalchemy/pool/impl.py", line 167, in _do_get
api02-1  |     return self._create_connection()
api02-1  |   File "/usr/local/lib/python3.9/site-packages/sqlalchemy/pool/base.py", line 393, in _create_connection
api02-1  |     return _ConnectionRecord(self)
api02-1  |   File "/usr/local/lib/python3.9/site-packages/sqlalchemy/pool/base.py", line 678, in __init__
api02-1  |     self.__connect()
api02-1  |   File "/usr/local/lib/python3.9/site-packages/sqlalchemy/pool/base.py", line 903, in __connect
api02-1  |     pool.logger.debug("Error on connect(): %s", e)
api02-1  |   File "/usr/local/lib/python3.9/site-packages/sqlalchemy/util/langhelpers.py", line 146, in __exit__
api02-1  |     raise exc_value.with_traceback(exc_tb)
api02-1  |   File "/usr/local/lib/python3.9/site-packages/sqlalchemy/pool/base.py", line 898, in __connect
api02-1  |     self.dbapi_connection = connection = pool._invoke_creator(self)
api02-1  |   File "/usr/local/lib/python3.9/site-packages/sqlalchemy/engine/create.py", line 645, in connect
api02-1  |     return dialect.connect(*cargs, **cparams)
api02-1  |   File "/usr/local/lib/python3.9/site-packages/sqlalchemy/engine/default.py", line 616, in connect
api02-1  |     return self.loaded_dbapi.connect(*cargs, **cparams)
api02-1  |   File "/usr/local/lib/python3.9/site-packages/MySQLdb/__init__.py", line 121, in Connect
api02-1  |     return Connection(*args, **kwargs)
api02-1  |   File "/usr/local/lib/python3.9/site-packages/MySQLdb/connections.py", line 195, in __init__
api02-1  |     super().__init__(*args, **kwargs2)
api02-1  | MySQLdb.OperationalError: (2002, "Can't connect to server on 'db' (115)")
api02-1  | 
api02-1  | The above exception was the direct cause of the following exception:
api02-1  | 
api02-1  | Traceback (most recent call last):
api02-1  |   File "/usr/local/lib/python3.9/site-packages/flask/app.py", line 1463, in wsgi_app
api02-1  |     response = self.full_dispatch_request()
api02-1  |   File "/usr/local/lib/python3.9/site-packages/flask/app.py", line 872, in full_dispatch_request
api02-1  |     rv = self.handle_user_exception(e)
api02-1  |   File "/usr/local/lib/python3.9/site-packages/flask/app.py", line 870, in full_dispatch_request
api02-1  |     rv = self.dispatch_request()
api02-1  |   File "/usr/local/lib/python3.9/site-packages/flask/app.py", line 855, in dispatch_request
api02-1  |     return self.ensure_sync(self.view_functions[rule.endpoint])(**view_args)  # type: ignore[no-any-return]
api02-1  |   File "/app/main.py", line 38, in get_transacoes
api02-1  |     cliente = session.query(Cliente).filter_by(id=cliente_id).first()
api02-1  |   File "/usr/local/lib/python3.9/site-packages/sqlalchemy/orm/query.py", line 2748, in first
api02-1  |     return self.limit(1)._iter().first()  # type: ignore
api02-1  |   File "/usr/local/lib/python3.9/site-packages/sqlalchemy/orm/query.py", line 2847, in _iter
api02-1  |     result: Union[ScalarResult[_T], Result[_T]] = self.session.execute(
api02-1  |   File "/usr/local/lib/python3.9/site-packages/sqlalchemy/orm/session.py", line 2308, in execute
api02-1  |     return self._execute_internal(
api02-1  |   File "/usr/local/lib/python3.9/site-packages/sqlalchemy/orm/session.py", line 2180, in _execute_internal
api02-1  |     conn = self._connection_for_bind(bind)
api02-1  |   File "/usr/local/lib/python3.9/site-packages/sqlalchemy/orm/session.py", line 2047, in _connection_for_bind
api02-1  |     return trans._connection_for_bind(engine, execution_options)
api02-1  |   File "<string>", line 2, in _connection_for_bind
api02-1  |   File "/usr/local/lib/python3.9/site-packages/sqlalchemy/orm/state_changes.py", line 139, in _go
api02-1  |     ret_value = fn(self, *arg, **kw)
api02-1  |   File "/usr/local/lib/python3.9/site-packages/sqlalchemy/orm/session.py", line 1143, in _connection_for_bind
api02-1  |     conn = bind.connect()
api02-1  |   File "/usr/local/lib/python3.9/site-packages/sqlalchemy/engine/base.py", line 3269, in connect
api02-1  |     return self._connection_cls(self)
api02-1  |   File "/usr/local/lib/python3.9/site-packages/sqlalchemy/engine/base.py", line 147, in __init__
api02-1  |     Connection._handle_dbapi_exception_noconnection(
api02-1  |   File "/usr/local/lib/python3.9/site-packages/sqlalchemy/engine/base.py", line 2431, in _handle_dbapi_exception_noconnection
api02-1  |     raise sqlalchemy_exception.with_traceback(exc_info[2]) from e
api02-1  |   File "/usr/local/lib/python3.9/site-packages/sqlalchemy/engine/base.py", line 145, in __init__
api02-1  |     self._dbapi_connection = engine.raw_connection()
api02-1  |   File "/usr/local/lib/python3.9/site-packages/sqlalchemy/engine/base.py", line 3293, in raw_connection
api02-1  |     return self.pool.connect()
api02-1  |   File "/usr/local/lib/python3.9/site-packages/sqlalchemy/pool/base.py", line 452, in connect
api02-1  |     return _ConnectionFairy._checkout(self)
api02-1  |   File "/usr/local/lib/python3.9/site-packages/sqlalchemy/pool/base.py", line 1269, in _checkout
api02-1  |     fairy = _ConnectionRecord.checkout(pool)
api02-1  |   File "/usr/local/lib/python3.9/site-packages/sqlalchemy/pool/base.py", line 716, in checkout
api02-1  |     rec = pool._do_get()
api02-1  |   File "/usr/local/lib/python3.9/site-packages/sqlalchemy/pool/impl.py", line 170, in _do_get
api02-1  |     self._dec_overflow()
api02-1  |   File "/usr/local/lib/python3.9/site-packages/sqlalchemy/util/langhelpers.py", line 146, in __exit__
api02-1  |     raise exc_value.with_traceback(exc_tb)
api02-1  |   File "/usr/local/lib/python3.9/site-packages/sqlalchemy/pool/impl.py", line 167, in _do_get
api02-1  |     return self._create_connection()
api02-1  |   File "/usr/local/lib/python3.9/site-packages/sqlalchemy/pool/base.py", line 393, in _create_connection
api02-1  |     return _ConnectionRecord(self)
api02-1  |   File "/usr/local/lib/python3.9/site-packages/sqlalchemy/pool/base.py", line 678, in __init__
api02-1  |     self.__connect()
api02-1  |   File "/usr/local/lib/python3.9/site-packages/sqlalchemy/pool/base.py", line 903, in __connect
api02-1  |     pool.logger.debug("Error on connect(): %s", e)
api02-1  |   File "/usr/local/lib/python3.9/site-packages/sqlalchemy/util/langhelpers.py", line 146, in __exit__
api02-1  |     raise exc_value.with_traceback(exc_tb)
api02-1  |   File "/usr/local/lib/python3.9/site-packages/sqlalchemy/pool/base.py", line 898, in __connect
api02-1  |     self.dbapi_connection = connection = pool._invoke_creator(self)
api02-1  |   File "/usr/local/lib/python3.9/site-packages/sqlalchemy/engine/create.py", line 645, in connect
api02-1  |     return dialect.connect(*cargs, **cparams)
api02-1  |   File "/usr/local/lib/python3.9/site-packages/sqlalchemy/engine/default.py", line 616, in connect
api02-1  |     return self.loaded_dbapi.connect(*cargs, **cparams)
api02-1  |   File "/usr/local/lib/python3.9/site-packages/MySQLdb/__init__.py", line 121, in Connect
api02-1  |     return Connection(*args, **kwargs)
api02-1  |   File "/usr/local/lib/python3.9/site-packages/MySQLdb/connections.py", line 195, in __init__
api02-1  |     super().__init__(*args, **kwargs2)
api02-1  | sqlalchemy.exc.OperationalError: (MySQLdb.OperationalError) (2002, "Can't connect to server on 'db' (115)")
api02-1  | (Background on this error at: https://sqlalche.me/e/20/e3q8)
api02-1  | 172.26.0.5 - - [12/Feb/2024 16:53:14] "[35m[1mGET /clientes/1/extrato HTTP/1.0[0m" 500 -
api02-1  | [2024-02-12 16:53:16,610] ERROR in app: Exception on /clientes/1/extrato [GET]
api02-1  | Traceback (most recent call last):
api02-1  |   File "/usr/local/lib/python3.9/site-packages/sqlalchemy/engine/base.py", line 145, in __init__
api02-1  |     self._dbapi_connection = engine.raw_connection()
api02-1  |   File "/usr/local/lib/python3.9/site-packages/sqlalchemy/engine/base.py", line 3293, in raw_connection
api02-1  |     return self.pool.connect()
api02-1  |   File "/usr/local/lib/python3.9/site-packages/sqlalchemy/pool/base.py", line 452, in connect
api02-1  |     return _ConnectionFairy._checkout(self)
api02-1  |   File "/usr/local/lib/python3.9/site-packages/sqlalchemy/pool/base.py", line 1269, in _checkout
api02-1  |     fairy = _ConnectionRecord.checkout(pool)
api02-1  |   File "/usr/local/lib/python3.9/site-packages/sqlalchemy/pool/base.py", line 716, in checkout
api02-1  |     rec = pool._do_get()
api02-1  |   File "/usr/local/lib/python3.9/site-packages/sqlalchemy/pool/impl.py", line 170, in _do_get
api02-1  |     self._dec_overflow()
api02-1  |   File "/usr/local/lib/python3.9/site-packages/sqlalchemy/util/langhelpers.py", line 146, in __exit__
api02-1  |     raise exc_value.with_traceback(exc_tb)
api02-1  |   File "/usr/local/lib/python3.9/site-packages/sqlalchemy/pool/impl.py", line 167, in _do_get
api02-1  |     return self._create_connection()
api02-1  |   File "/usr/local/lib/python3.9/site-packages/sqlalchemy/pool/base.py", line 393, in _create_connection
api02-1  |     return _ConnectionRecord(self)
api02-1  |   File "/usr/local/lib/python3.9/site-packages/sqlalchemy/pool/base.py", line 678, in __init__
api02-1  |     self.__connect()
api02-1  |   File "/usr/local/lib/python3.9/site-packages/sqlalchemy/pool/base.py", line 903, in __connect
api02-1  |     pool.logger.debug("Error on connect(): %s", e)
api02-1  |   File "/usr/local/lib/python3.9/site-packages/sqlalchemy/util/langhelpers.py", line 146, in __exit__
api02-1  |     raise exc_value.with_traceback(exc_tb)
api02-1  |   File "/usr/local/lib/python3.9/site-packages/sqlalchemy/pool/base.py", line 898, in __connect
api02-1  |     self.dbapi_connection = connection = pool._invoke_creator(self)
api02-1  |   File "/usr/local/lib/python3.9/site-packages/sqlalchemy/engine/create.py", line 645, in connect
api02-1  |     return dialect.connect(*cargs, **cparams)
api02-1  |   File "/usr/local/lib/python3.9/site-packages/sqlalchemy/engine/default.py", line 616, in connect
api02-1  |     return self.loaded_dbapi.connect(*cargs, **cparams)
api02-1  |   File "/usr/local/lib/python3.9/site-packages/MySQLdb/__init__.py", line 121, in Connect
api02-1  |     return Connection(*args, **kwargs)
api02-1  |   File "/usr/local/lib/python3.9/site-packages/MySQLdb/connections.py", line 195, in __init__
api02-1  |     super().__init__(*args, **kwargs2)
api02-1  | MySQLdb.OperationalError: (2002, "Can't connect to server on 'db' (115)")
api02-1  | 
api02-1  | The above exception was the direct cause of the following exception:
api02-1  | 
api02-1  | Traceback (most recent call last):
api02-1  |   File "/usr/local/lib/python3.9/site-packages/flask/app.py", line 1463, in wsgi_app
api02-1  |     response = self.full_dispatch_request()
api02-1  |   File "/usr/local/lib/python3.9/site-packages/flask/app.py", line 872, in full_dispatch_request
api02-1  |     rv = self.handle_user_exception(e)
api02-1  |   File "/usr/local/lib/python3.9/site-packages/flask/app.py", line 870, in full_dispatch_request
api02-1  |     rv = self.dispatch_request()
api02-1  |   File "/usr/local/lib/python3.9/site-packages/flask/app.py", line 855, in dispatch_request
api02-1  |     return self.ensure_sync(self.view_functions[rule.endpoint])(**view_args)  # type: ignore[no-any-return]
api02-1  |   File "/app/main.py", line 38, in get_transacoes
api02-1  |     cliente = session.query(Cliente).filter_by(id=cliente_id).first()
api02-1  |   File "/usr/local/lib/python3.9/site-packages/sqlalchemy/orm/query.py", line 2748, in first
api02-1  |     return self.limit(1)._iter().first()  # type: ignore
api02-1  |   File "/usr/local/lib/python3.9/site-packages/sqlalchemy/orm/query.py", line 2847, in _iter
api02-1  |     result: Union[ScalarResult[_T], Result[_T]] = self.session.execute(
api02-1  |   File "/usr/local/lib/python3.9/site-packages/sqlalchemy/orm/session.py", line 2308, in execute
api02-1  |     return self._execute_internal(
api02-1  |   File "/usr/local/lib/python3.9/site-packages/sqlalchemy/orm/session.py", line 2180, in _execute_internal
api02-1  |     conn = self._connection_for_bind(bind)
api02-1  |   File "/usr/local/lib/python3.9/site-packages/sqlalchemy/orm/session.py", line 2047, in _connection_for_bind
api02-1  |     return trans._connection_for_bind(engine, execution_options)
api02-1  |   File "<string>", line 2, in _connection_for_bind
api02-1  |   File "/usr/local/lib/python3.9/site-packages/sqlalchemy/orm/state_changes.py", line 139, in _go
api02-1  |     ret_value = fn(self, *arg, **kw)
api02-1  |   File "/usr/local/lib/python3.9/site-packages/sqlalchemy/orm/session.py", line 1143, in _connection_for_bind
api02-1  |     conn = bind.connect()
api02-1  |   File "/usr/local/lib/python3.9/site-packages/sqlalchemy/engine/base.py", line 3269, in connect
api02-1  |     return self._connection_cls(self)
api02-1  |   File "/usr/local/lib/python3.9/site-packages/sqlalchemy/engine/base.py", line 147, in __init__
api02-1  |     Connection._handle_dbapi_exception_noconnection(
api02-1  |   File "/usr/local/lib/python3.9/site-packages/sqlalchemy/engine/base.py", line 2431, in _handle_dbapi_exception_noconnection
api02-1  |     raise sqlalchemy_exception.with_traceback(exc_info[2]) from e
api02-1  |   File "/usr/local/lib/python3.9/site-packages/sqlalchemy/engine/base.py", line 145, in __init__
api02-1  |     self._dbapi_connection = engine.raw_connection()
api02-1  |   File "/usr/local/lib/python3.9/site-packages/sqlalchemy/engine/base.py", line 3293, in raw_connection
api02-1  |     return self.pool.connect()
api02-1  |   File "/usr/local/lib/python3.9/site-packages/sqlalchemy/pool/base.py", line 452, in connect
api02-1  |     return _ConnectionFairy._checkout(self)
api02-1  |   File "/usr/local/lib/python3.9/site-packages/sqlalchemy/pool/base.py", line 1269, in _checkout
api02-1  |     fairy = _ConnectionRecord.checkout(pool)
api02-1  |   File "/usr/local/lib/python3.9/site-packages/sqlalchemy/pool/base.py", line 716, in checkout
api02-1  |     rec = pool._do_get()
api02-1  |   File "/usr/local/lib/python3.9/site-packages/sqlalchemy/pool/impl.py", line 170, in _do_get
api02-1  |     self._dec_overflow()
api02-1  |   File "/usr/local/lib/python3.9/site-packages/sqlalchemy/util/langhelpers.py", line 146, in __exit__
api02-1  |     raise exc_value.with_traceback(exc_tb)
api02-1  |   File "/usr/local/lib/python3.9/site-packages/sqlalchemy/pool/impl.py", line 167, in _do_get
api02-1  |     return self._create_connection()
api02-1  |   File "/usr/local/lib/python3.9/site-packages/sqlalchemy/pool/base.py", line 393, in _create_connection
api02-1  |     return _ConnectionRecord(self)
api02-1  |   File "/usr/local/lib/python3.9/site-packages/sqlalchemy/pool/base.py", line 678, in __init__
api02-1  |     self.__connect()
api02-1  |   File "/usr/local/lib/python3.9/site-packages/sqlalchemy/pool/base.py", line 903, in __connect
api02-1  |     pool.logger.debug("Error on connect(): %s", e)
api02-1  |   File "/usr/local/lib/python3.9/site-packages/sqlalchemy/util/langhelpers.py", line 146, in __exit__
api02-1  |     raise exc_value.with_traceback(exc_tb)
api02-1  |   File "/usr/local/lib/python3.9/site-packages/sqlalchemy/pool/base.py", line 898, in __connect
api02-1  |     self.dbapi_connection = connection = pool._invoke_creator(self)
api02-1  |   File "/usr/local/lib/python3.9/site-packages/sqlalchemy/engine/create.py", line 645, in connect
api02-1  |     return dialect.connect(*cargs, **cparams)
api02-1  |   File "/usr/local/lib/python3.9/site-packages/sqlalchemy/engine/default.py", line 616, in connect
api02-1  |     return self.loaded_dbapi.connect(*cargs, **cparams)
api02-1  |   File "/usr/local/lib/python3.9/site-packages/MySQLdb/__init__.py", line 121, in Connect
api02-1  |     return Connection(*args, **kwargs)
api02-1  |   File "/usr/local/lib/python3.9/site-packages/MySQLdb/connections.py", line 195, in __init__
api02-1  |     super().__init__(*args, **kwargs2)
api02-1  | sqlalchemy.exc.OperationalError: (MySQLdb.OperationalError) (2002, "Can't connect to server on 'db' (115)")
api02-1  | (Background on this error at: https://sqlalche.me/e/20/e3q8)
api02-1  | 172.26.0.5 - - [12/Feb/2024 16:53:16] "[35m[1mGET /clientes/1/extrato HTTP/1.0[0m" 500 -
db-1     | 2024-02-12T16:53:17.795509Z 0 [System] [MY-015018] [Server] MySQL Server Initialization - end.
db-1     | 2024-02-12 16:53:17+00:00 [Note] [Entrypoint]: Database files initialized
db-1     | 2024-02-12 16:53:17+00:00 [Note] [Entrypoint]: Starting temporary server
api01-1  | [2024-02-12 16:53:18,631] ERROR in app: Exception on /clientes/1/extrato [GET]
api01-1  | Traceback (most recent call last):
api01-1  |   File "/usr/local/lib/python3.9/site-packages/sqlalchemy/engine/base.py", line 145, in __init__
api01-1  |     self._dbapi_connection = engine.raw_connection()
api01-1  |   File "/usr/local/lib/python3.9/site-packages/sqlalchemy/engine/base.py", line 3293, in raw_connection
api01-1  |     return self.pool.connect()
api01-1  |   File "/usr/local/lib/python3.9/site-packages/sqlalchemy/pool/base.py", line 452, in connect
api01-1  |     return _ConnectionFairy._checkout(self)
api01-1  |   File "/usr/local/lib/python3.9/site-packages/sqlalchemy/pool/base.py", line 1269, in _checkout
api01-1  |     fairy = _ConnectionRecord.checkout(pool)
api01-1  |   File "/usr/local/lib/python3.9/site-packages/sqlalchemy/pool/base.py", line 716, in checkout
api01-1  |     rec = pool._do_get()
api01-1  |   File "/usr/local/lib/python3.9/site-packages/sqlalchemy/pool/impl.py", line 170, in _do_get
api01-1  |     self._dec_overflow()
api01-1  |   File "/usr/local/lib/python3.9/site-packages/sqlalchemy/util/langhelpers.py", line 146, in __exit__
api01-1  |     raise exc_value.with_traceback(exc_tb)
api01-1  |   File "/usr/local/lib/python3.9/site-packages/sqlalchemy/pool/impl.py", line 167, in _do_get
api01-1  |     return self._create_connection()
api01-1  |   File "/usr/local/lib/python3.9/site-packages/sqlalchemy/pool/base.py", line 393, in _create_connection
api01-1  |     return _ConnectionRecord(self)
api01-1  |   File "/usr/local/lib/python3.9/site-packages/sqlalchemy/pool/base.py", line 678, in __init__
api01-1  |     self.__connect()
api01-1  |   File "/usr/local/lib/python3.9/site-packages/sqlalchemy/pool/base.py", line 903, in __connect
api01-1  |     pool.logger.debug("Error on connect(): %s", e)
api01-1  |   File "/usr/local/lib/python3.9/site-packages/sqlalchemy/util/langhelpers.py", line 146, in __exit__
api01-1  |     raise exc_value.with_traceback(exc_tb)
api01-1  |   File "/usr/local/lib/python3.9/site-packages/sqlalchemy/pool/base.py", line 898, in __connect
api01-1  |     self.dbapi_connection = connection = pool._invoke_creator(self)
api01-1  |   File "/usr/local/lib/python3.9/site-packages/sqlalchemy/engine/create.py", line 645, in connect
api01-1  |     return dialect.connect(*cargs, **cparams)
api01-1  |   File "/usr/local/lib/python3.9/site-packages/sqlalchemy/engine/default.py", line 616, in connect
api01-1  |     return self.loaded_dbapi.connect(*cargs, **cparams)
api01-1  |   File "/usr/local/lib/python3.9/site-packages/MySQLdb/__init__.py", line 121, in Connect
api01-1  |     return Connection(*args, **kwargs)
api01-1  |   File "/usr/local/lib/python3.9/site-packages/MySQLdb/connections.py", line 195, in __init__
api01-1  |     super().__init__(*args, **kwargs2)
api01-1  | MySQLdb.OperationalError: (2002, "Can't connect to server on 'db' (115)")
api01-1  | 
api01-1  | The above exception was the direct cause of the following exception:
api01-1  | 
api01-1  | Traceback (most recent call last):
api01-1  |   File "/usr/local/lib/python3.9/site-packages/flask/app.py", line 1463, in wsgi_app
api01-1  |     response = self.full_dispatch_request()
api01-1  |   File "/usr/local/lib/python3.9/site-packages/flask/app.py", line 872, in full_dispatch_request
api01-1  |     rv = self.handle_user_exception(e)
api01-1  |   File "/usr/local/lib/python3.9/site-packages/flask/app.py", line 870, in full_dispatch_request
api01-1  |     rv = self.dispatch_request()
api01-1  |   File "/usr/local/lib/python3.9/site-packages/flask/app.py", line 855, in dispatch_request
api01-1  |     return self.ensure_sync(self.view_functions[rule.endpoint])(**view_args)  # type: ignore[no-any-return]
api01-1  |   File "/app/main.py", line 38, in get_transacoes
api01-1  |     cliente = session.query(Cliente).filter_by(id=cliente_id).first()
api01-1  |   File "/usr/local/lib/python3.9/site-packages/sqlalchemy/orm/query.py", line 2748, in first
api01-1  |     return self.limit(1)._iter().first()  # type: ignore
api01-1  |   File "/usr/local/lib/python3.9/site-packages/sqlalchemy/orm/query.py", line 2847, in _iter
api01-1  |     result: Union[ScalarResult[_T], Result[_T]] = self.session.execute(
api01-1  |   File "/usr/local/lib/python3.9/site-packages/sqlalchemy/orm/session.py", line 2308, in execute
api01-1  |     return self._execute_internal(
api01-1  |   File "/usr/local/lib/python3.9/site-packages/sqlalchemy/orm/session.py", line 2180, in _execute_internal
api01-1  |     conn = self._connection_for_bind(bind)
api01-1  |   File "/usr/local/lib/python3.9/site-packages/sqlalchemy/orm/session.py", line 2047, in _connection_for_bind
api01-1  |     return trans._connection_for_bind(engine, execution_options)
api01-1  |   File "<string>", line 2, in _connection_for_bind
api01-1  |   File "/usr/local/lib/python3.9/site-packages/sqlalchemy/orm/state_changes.py", line 139, in _go
api01-1  |     ret_value = fn(self, *arg, **kw)
api01-1  |   File "/usr/local/lib/python3.9/site-packages/sqlalchemy/orm/session.py", line 1143, in _connection_for_bind
api01-1  |     conn = bind.connect()
api01-1  |   File "/usr/local/lib/python3.9/site-packages/sqlalchemy/engine/base.py", line 3269, in connect
api01-1  |     return self._connection_cls(self)
api01-1  |   File "/usr/local/lib/python3.9/site-packages/sqlalchemy/engine/base.py", line 147, in __init__
api01-1  |     Connection._handle_dbapi_exception_noconnection(
api01-1  |   File "/usr/local/lib/python3.9/site-packages/sqlalchemy/engine/base.py", line 2431, in _handle_dbapi_exception_noconnection
api01-1  |     raise sqlalchemy_exception.with_traceback(exc_info[2]) from e
api01-1  |   File "/usr/local/lib/python3.9/site-packages/sqlalchemy/engine/base.py", line 145, in __init__
api01-1  |     self._dbapi_connection = engine.raw_connection()
api01-1  |   File "/usr/local/lib/python3.9/site-packages/sqlalchemy/engine/base.py", line 3293, in raw_connection
api01-1  |     return self.pool.connect()
api01-1  |   File "/usr/local/lib/python3.9/site-packages/sqlalchemy/pool/base.py", line 452, in connect
api01-1  |     return _ConnectionFairy._checkout(self)
api01-1  |   File "/usr/local/lib/python3.9/site-packages/sqlalchemy/pool/base.py", line 1269, in _checkout
api01-1  |     fairy = _ConnectionRecord.checkout(pool)
api01-1  |   File "/usr/local/lib/python3.9/site-packages/sqlalchemy/pool/base.py", line 716, in checkout
api01-1  |     rec = pool._do_get()
api01-1  |   File "/usr/local/lib/python3.9/site-packages/sqlalchemy/pool/impl.py", line 170, in _do_get
api01-1  |     self._dec_overflow()
api01-1  |   File "/usr/local/lib/python3.9/site-packages/sqlalchemy/util/langhelpers.py", line 146, in __exit__
api01-1  |     raise exc_value.with_traceback(exc_tb)
api01-1  |   File "/usr/local/lib/python3.9/site-packages/sqlalchemy/pool/impl.py", line 167, in _do_get
api01-1  |     return self._create_connection()
api01-1  |   File "/usr/local/lib/python3.9/site-packages/sqlalchemy/pool/base.py", line 393, in _create_connection
api01-1  |     return _ConnectionRecord(self)
api01-1  |   File "/usr/local/lib/python3.9/site-packages/sqlalchemy/pool/base.py", line 678, in __init__
api01-1  |     self.__connect()
api01-1  |   File "/usr/local/lib/python3.9/site-packages/sqlalchemy/pool/base.py", line 903, in __connect
api01-1  |     pool.logger.debug("Error on connect(): %s", e)
api01-1  |   File "/usr/local/lib/python3.9/site-packages/sqlalchemy/util/langhelpers.py", line 146, in __exit__
api01-1  |     raise exc_value.with_traceback(exc_tb)
api01-1  |   File "/usr/local/lib/python3.9/site-packages/sqlalchemy/pool/base.py", line 898, in __connect
api01-1  |     self.dbapi_connection = connection = pool._invoke_creator(self)
api01-1  |   File "/usr/local/lib/python3.9/site-packages/sqlalchemy/engine/create.py", line 645, in connect
api01-1  |     return dialect.connect(*cargs, **cparams)
api01-1  |   File "/usr/local/lib/python3.9/site-packages/sqlalchemy/engine/default.py", line 616, in connect
api01-1  |     return self.loaded_dbapi.connect(*cargs, **cparams)
api01-1  |   File "/usr/local/lib/python3.9/site-packages/MySQLdb/__init__.py", line 121, in Connect
api01-1  |     return Connection(*args, **kwargs)
api01-1  |   File "/usr/local/lib/python3.9/site-packages/MySQLdb/connections.py", line 195, in __init__
api01-1  |     super().__init__(*args, **kwargs2)
api01-1  | sqlalchemy.exc.OperationalError: (MySQLdb.OperationalError) (2002, "Can't connect to server on 'db' (115)")
api01-1  | (Background on this error at: https://sqlalche.me/e/20/e3q8)
api01-1  | 172.26.0.5 - - [12/Feb/2024 16:53:18] "[35m[1mGET /clientes/1/extrato HTTP/1.0[0m" 500 -
db-1     | 2024-02-12T16:53:18.091314Z 0 [System] [MY-015015] [Server] MySQL Server - start.
db-1     | 2024-02-12T16:53:20.111511Z 0 [System] [MY-010116] [Server] /usr/sbin/mysqld (mysqld 8.3.0) starting as process 123
db-1     | 2024-02-12T16:53:20.419202Z 1 [System] [MY-013576] [InnoDB] InnoDB initialization has started.
api02-1  | [2024-02-12 16:53:20,648] ERROR in app: Exception on /clientes/1/extrato [GET]
api02-1  | Traceback (most recent call last):
api02-1  |   File "/usr/local/lib/python3.9/site-packages/sqlalchemy/engine/base.py", line 145, in __init__
api02-1  |     self._dbapi_connection = engine.raw_connection()
api02-1  |   File "/usr/local/lib/python3.9/site-packages/sqlalchemy/engine/base.py", line 3293, in raw_connection
api02-1  |     return self.pool.connect()
api02-1  |   File "/usr/local/lib/python3.9/site-packages/sqlalchemy/pool/base.py", line 452, in connect
api02-1  |     return _ConnectionFairy._checkout(self)
api02-1  |   File "/usr/local/lib/python3.9/site-packages/sqlalchemy/pool/base.py", line 1269, in _checkout
api02-1  |     fairy = _ConnectionRecord.checkout(pool)
api02-1  |   File "/usr/local/lib/python3.9/site-packages/sqlalchemy/pool/base.py", line 716, in checkout
api02-1  |     rec = pool._do_get()
api02-1  |   File "/usr/local/lib/python3.9/site-packages/sqlalchemy/pool/impl.py", line 170, in _do_get
api02-1  |     self._dec_overflow()
api02-1  |   File "/usr/local/lib/python3.9/site-packages/sqlalchemy/util/langhelpers.py", line 146, in __exit__
api02-1  |     raise exc_value.with_traceback(exc_tb)
api02-1  |   File "/usr/local/lib/python3.9/site-packages/sqlalchemy/pool/impl.py", line 167, in _do_get
api02-1  |     return self._create_connection()
api02-1  |   File "/usr/local/lib/python3.9/site-packages/sqlalchemy/pool/base.py", line 393, in _create_connection
api02-1  |     return _ConnectionRecord(self)
api02-1  |   File "/usr/local/lib/python3.9/site-packages/sqlalchemy/pool/base.py", line 678, in __init__
api02-1  |     self.__connect()
api02-1  |   File "/usr/local/lib/python3.9/site-packages/sqlalchemy/pool/base.py", line 903, in __connect
api02-1  |     pool.logger.debug("Error on connect(): %s", e)
api02-1  |   File "/usr/local/lib/python3.9/site-packages/sqlalchemy/util/langhelpers.py", line 146, in __exit__
api02-1  |     raise exc_value.with_traceback(exc_tb)
api02-1  |   File "/usr/local/lib/python3.9/site-packages/sqlalchemy/pool/base.py", line 898, in __connect
api02-1  |     self.dbapi_connection = connection = pool._invoke_creator(self)
api02-1  |   File "/usr/local/lib/python3.9/site-packages/sqlalchemy/engine/create.py", line 645, in connect
api02-1  |     return dialect.connect(*cargs, **cparams)
api02-1  |   File "/usr/local/lib/python3.9/site-packages/sqlalchemy/engine/default.py", line 616, in connect
api02-1  |     return self.loaded_dbapi.connect(*cargs, **cparams)
api02-1  |   File "/usr/local/lib/python3.9/site-packages/MySQLdb/__init__.py", line 121, in Connect
api02-1  |     return Connection(*args, **kwargs)
api02-1  |   File "/usr/local/lib/python3.9/site-packages/MySQLdb/connections.py", line 195, in __init__
api02-1  |     super().__init__(*args, **kwargs2)
api02-1  | MySQLdb.OperationalError: (2002, "Can't connect to server on 'db' (115)")
api02-1  | 
api02-1  | The above exception was the direct cause of the following exception:
api02-1  | 
api02-1  | Traceback (most recent call last):
api02-1  |   File "/usr/local/lib/python3.9/site-packages/flask/app.py", line 1463, in wsgi_app
api02-1  |     response = self.full_dispatch_request()
api02-1  |   File "/usr/local/lib/python3.9/site-packages/flask/app.py", line 872, in full_dispatch_request
api02-1  |     rv = self.handle_user_exception(e)
api02-1  |   File "/usr/local/lib/python3.9/site-packages/flask/app.py", line 870, in full_dispatch_request
api02-1  |     rv = self.dispatch_request()
api02-1  |   File "/usr/local/lib/python3.9/site-packages/flask/app.py", line 855, in dispatch_request
api02-1  |     return self.ensure_sync(self.view_functions[rule.endpoint])(**view_args)  # type: ignore[no-any-return]
api02-1  |   File "/app/main.py", line 38, in get_transacoes
api02-1  |     cliente = session.query(Cliente).filter_by(id=cliente_id).first()
api02-1  |   File "/usr/local/lib/python3.9/site-packages/sqlalchemy/orm/query.py", line 2748, in first
api02-1  |     return self.limit(1)._iter().first()  # type: ignore
api02-1  |   File "/usr/local/lib/python3.9/site-packages/sqlalchemy/orm/query.py", line 2847, in _iter
api02-1  |     result: Union[ScalarResult[_T], Result[_T]] = self.session.execute(
api02-1  |   File "/usr/local/lib/python3.9/site-packages/sqlalchemy/orm/session.py", line 2308, in execute
api02-1  |     return self._execute_internal(
api02-1  |   File "/usr/local/lib/python3.9/site-packages/sqlalchemy/orm/session.py", line 2180, in _execute_internal
api02-1  |     conn = self._connection_for_bind(bind)
api02-1  |   File "/usr/local/lib/python3.9/site-packages/sqlalchemy/orm/session.py", line 2047, in _connection_for_bind
api02-1  |     return trans._connection_for_bind(engine, execution_options)
api02-1  |   File "<string>", line 2, in _connection_for_bind
api02-1  |   File "/usr/local/lib/python3.9/site-packages/sqlalchemy/orm/state_changes.py", line 139, in _go
api02-1  |     ret_value = fn(self, *arg, **kw)
api02-1  |   File "/usr/local/lib/python3.9/site-packages/sqlalchemy/orm/session.py", line 1143, in _connection_for_bind
api02-1  |     conn = bind.connect()
api02-1  |   File "/usr/local/lib/python3.9/site-packages/sqlalchemy/engine/base.py", line 3269, in connect
api02-1  |     return self._connection_cls(self)
api02-1  |   File "/usr/local/lib/python3.9/site-packages/sqlalchemy/engine/base.py", line 147, in __init__
api02-1  |     Connection._handle_dbapi_exception_noconnection(
api02-1  |   File "/usr/local/lib/python3.9/site-packages/sqlalchemy/engine/base.py", line 2431, in _handle_dbapi_exception_noconnection
api02-1  |     raise sqlalchemy_exception.with_traceback(exc_info[2]) from e
api02-1  |   File "/usr/local/lib/python3.9/site-packages/sqlalchemy/engine/base.py", line 145, in __init__
api02-1  |     self._dbapi_connection = engine.raw_connection()
api02-1  |   File "/usr/local/lib/python3.9/site-packages/sqlalchemy/engine/base.py", line 3293, in raw_connection
api02-1  |     return self.pool.connect()
api02-1  |   File "/usr/local/lib/python3.9/site-packages/sqlalchemy/pool/base.py", line 452, in connect
api02-1  |     return _ConnectionFairy._checkout(self)
api02-1  |   File "/usr/local/lib/python3.9/site-packages/sqlalchemy/pool/base.py", line 1269, in _checkout
api02-1  |     fairy = _ConnectionRecord.checkout(pool)
api02-1  |   File "/usr/local/lib/python3.9/site-packages/sqlalchemy/pool/base.py", line 716, in checkout
api02-1  |     rec = pool._do_get()
api02-1  |   File "/usr/local/lib/python3.9/site-packages/sqlalchemy/pool/impl.py", line 170, in _do_get
api02-1  |     self._dec_overflow()
api02-1  |   File "/usr/local/lib/python3.9/site-packages/sqlalchemy/util/langhelpers.py", line 146, in __exit__
api02-1  |     raise exc_value.with_traceback(exc_tb)
api02-1  |   File "/usr/local/lib/python3.9/site-packages/sqlalchemy/pool/impl.py", line 167, in _do_get
api02-1  |     return self._create_connection()
api02-1  |   File "/usr/local/lib/python3.9/site-packages/sqlalchemy/pool/base.py", line 393, in _create_connection
api02-1  |     return _ConnectionRecord(self)
api02-1  |   File "/usr/local/lib/python3.9/site-packages/sqlalchemy/pool/base.py", line 678, in __init__
api02-1  |     self.__connect()
api02-1  |   File "/usr/local/lib/python3.9/site-packages/sqlalchemy/pool/base.py", line 903, in __connect
api02-1  |     pool.logger.debug("Error on connect(): %s", e)
api02-1  |   File "/usr/local/lib/python3.9/site-packages/sqlalchemy/util/langhelpers.py", line 146, in __exit__
api02-1  |     raise exc_value.with_traceback(exc_tb)
api02-1  |   File "/usr/local/lib/python3.9/site-packages/sqlalchemy/pool/base.py", line 898, in __connect
api02-1  |     self.dbapi_connection = connection = pool._invoke_creator(self)
api02-1  |   File "/usr/local/lib/python3.9/site-packages/sqlalchemy/engine/create.py", line 645, in connect
api02-1  |     return dialect.connect(*cargs, **cparams)
api02-1  |   File "/usr/local/lib/python3.9/site-packages/sqlalchemy/engine/default.py", line 616, in connect
api02-1  |     return self.loaded_dbapi.connect(*cargs, **cparams)
api02-1  |   File "/usr/local/lib/python3.9/site-packages/MySQLdb/__init__.py", line 121, in Connect
api02-1  |     return Connection(*args, **kwargs)
api02-1  |   File "/usr/local/lib/python3.9/site-packages/MySQLdb/connections.py", line 195, in __init__
api02-1  |     super().__init__(*args, **kwargs2)
