 Network rinha-nginx-2024q1  Creating
 Network rinha-nginx-2024q1  Created
 Container ramondelemos-db-1  Creating
 Container ramondelemos-db-1  Created
 Container ramondelemos-api02-1  Creating
 Container ramondelemos-api01-1  Creating
 Container ramondelemos-api02-1  Created
 Container ramondelemos-api01-1  Created
 Container ramondelemos-nginx-1  Creating
 Container ramondelemos-nginx-1  Created
Attaching to api01-1, api02-1, db-1, nginx-1
db-1     | The files belonging to this database system will be owned by user "postgres".
db-1     | This user must also own the server process.
db-1     | 
db-1     | The database cluster will be initialized with locale "en_US.utf8".
db-1     | The default database encoding has accordingly been set to "UTF8".
db-1     | The default text search configuration will be set to "english".
db-1     | 
db-1     | Data page checksums are disabled.
db-1     | 
db-1     | fixing permissions on existing directory /var/lib/postgresql/data ... ok
db-1     | creating subdirectories ... ok
db-1     | selecting dynamic shared memory implementation ... posix
db-1     | selecting default max_connections ... 100
db-1     | selecting default shared_buffers ... 128MB
db-1     | selecting default time zone ... UTC
db-1     | creating configuration files ... ok
nginx-1  | /docker-entrypoint.sh: /docker-entrypoint.d/ is not empty, will attempt to perform configuration
nginx-1  | /docker-entrypoint.sh: Looking for shell scripts in /docker-entrypoint.d/
nginx-1  | /docker-entrypoint.sh: Launching /docker-entrypoint.d/10-listen-on-ipv6-by-default.sh
nginx-1  | 10-listen-on-ipv6-by-default.sh: info: Getting the checksum of /etc/nginx/conf.d/default.conf
nginx-1  | 10-listen-on-ipv6-by-default.sh: info: Enabled listen on IPv6 in /etc/nginx/conf.d/default.conf
nginx-1  | /docker-entrypoint.sh: Sourcing /docker-entrypoint.d/15-local-resolvers.envsh
nginx-1  | /docker-entrypoint.sh: Launching /docker-entrypoint.d/20-envsubst-on-templates.sh
nginx-1  | /docker-entrypoint.sh: Launching /docker-entrypoint.d/30-tune-worker-processes.sh
nginx-1  | /docker-entrypoint.sh: Configuration complete; ready for start up
db-1     | running bootstrap script ... ok
nginx-1  | 2024/02/14 01:20:50 [error] 29#29: *1 connect() failed (111: Connection refused) while connecting to upstream, client: 172.20.0.1, server: , request: "GET /clientes/1/extrato HTTP/1.1", upstream: "http://172.20.0.4:4001/clientes/1/extrato", host: "localhost:9999"
nginx-1  | 2024/02/14 01:20:50 [error] 29#29: *1 connect() failed (111: Connection refused) while connecting to upstream, client: 172.20.0.1, server: , request: "GET /clientes/1/extrato HTTP/1.1", upstream: "http://172.20.0.3:4001/clientes/1/extrato", host: "localhost:9999"
api02-1  | 
api02-1  | 22:20:51.957 [error] Postgrex.Protocol (#PID<0.1311.0>) failed to connect: ** (DBConnection.ConnectionError) tcp connect (db:5432): connection refused - :econnrefused
api02-1  | 
api02-1  | 22:20:51.957 [error] Postgrex.Protocol (#PID<0.1331.0>) failed to connect: ** (DBConnection.ConnectionError) tcp connect (db:5432): connection refused - :econnrefused
api02-1  | 
api02-1  | 22:20:51.957 [error] Postgrex.Protocol (#PID<0.1312.0>) failed to connect: ** (DBConnection.ConnectionError) tcp connect (db:5432): connection refused - :econnrefused
api02-1  | 
api02-1  | 22:20:51.957 [error] Postgrex.Protocol (#PID<0.1307.0>) failed to connect: ** (DBConnection.ConnectionError) tcp connect (db:5432): connection refused - :econnrefused
api02-1  | 
api02-1  | 22:20:51.957 [error] Postgrex.Protocol (#PID<0.1308.0>) failed to connect: ** (DBConnection.ConnectionError) tcp connect (db:5432): connection refused - :econnrefused
api02-1  | 
api02-1  | 22:20:51.957 [error] Postgrex.Protocol (#PID<0.1313.0>) failed to connect: ** (DBConnection.ConnectionError) tcp connect (db:5432): connection refused - :econnrefused
api02-1  | 
api02-1  | 22:20:51.957 [error] Postgrex.Protocol (#PID<0.1314.0>) failed to connect: ** (DBConnection.ConnectionError) tcp connect (db:5432): connection refused - :econnrefused
api02-1  | 
api02-1  | 22:20:51.957 [error] Postgrex.Protocol (#PID<0.1315.0>) failed to connect: ** (DBConnection.ConnectionError) tcp connect (db:5432): connection refused - :econnrefused
api02-1  | 
api02-1  | 22:20:51.957 [error] Postgrex.Protocol (#PID<0.1316.0>) failed to connect: ** (DBConnection.ConnectionError) tcp connect (db:5432): connection refused - :econnrefused
api02-1  | 
api02-1  | 22:20:51.957 [error] Postgrex.Protocol (#PID<0.1317.0>) failed to connect: ** (DBConnection.ConnectionError) tcp connect (db:5432): connection refused - :econnrefused
api02-1  | 
api02-1  | 22:20:51.957 [error] Postgrex.Protocol (#PID<0.1318.0>) failed to connect: ** (DBConnection.ConnectionError) tcp connect (db:5432): connection refused - :econnrefused
api02-1  | 
api02-1  | 22:20:51.957 [error] Postgrex.Protocol (#PID<0.1322.0>) failed to connect: ** (DBConnection.ConnectionError) tcp connect (db:5432): connection refused - :econnrefused
api02-1  | 
api02-1  | 22:20:51.957 [error] Postgrex.Protocol (#PID<0.1323.0>) failed to connect: ** (DBConnection.ConnectionError) tcp connect (db:5432): connection refused - :econnrefused
api02-1  | 
api02-1  | 22:20:51.957 [error] Postgrex.Protocol (#PID<0.1324.0>) failed to connect: ** (DBConnection.ConnectionError) tcp connect (db:5432): connection refused - :econnrefused
api02-1  | 
api02-1  | 22:20:51.957 [error] Postgrex.Protocol (#PID<0.1325.0>) failed to connect: ** (DBConnection.ConnectionError) tcp connect (db:5432): connection refused - :econnrefused
api02-1  | 
api02-1  | 22:20:51.957 [error] Postgrex.Protocol (#PID<0.1326.0>) failed to connect: ** (DBConnection.ConnectionError) tcp connect (db:5432): connection refused - :econnrefused
api02-1  | 
api02-1  | 22:20:51.957 [error] Postgrex.Protocol (#PID<0.1327.0>) failed to connect: ** (DBConnection.ConnectionError) tcp connect (db:5432): connection refused - :econnrefused
api02-1  | 
api02-1  | 22:20:51.957 [error] Postgrex.Protocol (#PID<0.1328.0>) failed to connect: ** (DBConnection.ConnectionError) tcp connect (db:5432): connection refused - :econnrefused
api02-1  | 
api02-1  | 22:20:51.957 [error] Postgrex.Protocol (#PID<0.1329.0>) failed to connect: ** (DBConnection.ConnectionError) tcp connect (db:5432): connection refused - :econnrefused
api02-1  | 
api02-1  | 22:20:51.957 [error] Postgrex.Protocol (#PID<0.1330.0>) failed to connect: ** (DBConnection.ConnectionError) tcp connect (db:5432): connection refused - :econnrefused
api01-1  | 
api01-1  | 22:20:51.971 [error] Postgrex.Protocol (#PID<0.1306.0>) failed to connect: ** (DBConnection.ConnectionError) tcp connect (db:5432): connection refused - :econnrefused
api01-1  | 
api01-1  | 22:20:51.972 [error] Postgrex.Protocol (#PID<0.1312.0>) failed to connect: ** (DBConnection.ConnectionError) tcp connect (db:5432): connection refused - :econnrefused
api01-1  | 
api01-1  | 22:20:51.973 [error] Postgrex.Protocol (#PID<0.1316.0>) failed to connect: ** (DBConnection.ConnectionError) tcp connect (db:5432): connection refused - :econnrefused
api01-1  | 
api01-1  | 22:20:51.973 [error] Postgrex.Protocol (#PID<0.1317.0>) failed to connect: ** (DBConnection.ConnectionError) tcp connect (db:5432): connection refused - :econnrefused
db-1     | sh: locale: not found
db-1     | 2024-02-14 01:20:52.103 UTC [31] WARNING:  no usable system locales were found
nginx-1  | 2024/02/14 01:20:52 [error] 29#29: *4 no live upstreams while connecting to upstream, client: 172.20.0.1, server: , request: "GET /clientes/1/extrato HTTP/1.1", upstream: "http://api/clientes/1/extrato", host: "localhost:9999"
api02-1  | 
api02-1  | 22:20:53.119 [error] Postgrex.Protocol (#PID<0.1325.0>) failed to connect: ** (DBConnection.ConnectionError) tcp connect (db:5432): connection refused - :econnrefused
api02-1  | 
api02-1  | 22:20:53.163 [error] Postgrex.Protocol (#PID<0.1323.0>) failed to connect: ** (DBConnection.ConnectionError) tcp connect (db:5432): connection refused - :econnrefused
api02-1  | 
api02-1  | 22:20:53.213 [error] Postgrex.Protocol (#PID<0.1324.0>) failed to connect: ** (DBConnection.ConnectionError) tcp connect (db:5432): connection refused - :econnrefused
api02-1  | 
api02-1  | 22:20:53.247 [error] Postgrex.Protocol (#PID<0.1311.0>) failed to connect: ** (DBConnection.ConnectionError) tcp connect (db:5432): connection refused - :econnrefused
api02-1  | 
api02-1  | 22:20:53.291 [error] Postgrex.Protocol (#PID<0.1317.0>) failed to connect: ** (DBConnection.ConnectionError) tcp connect (db:5432): connection refused - :econnrefused
api01-1  | 
api01-1  | 22:20:53.480 [error] Postgrex.Protocol (#PID<0.1317.0>) failed to connect: ** (DBConnection.ConnectionError) tcp connect (db:5432): connection refused - :econnrefused
api02-1  | 
api02-1  | 22:20:53.485 [error] Postgrex.Protocol (#PID<0.1331.0>) failed to connect: ** (DBConnection.ConnectionError) tcp connect (db:5432): connection refused - :econnrefused
api02-1  | 
api02-1  | 22:20:53.568 [error] Postgrex.Protocol (#PID<0.1312.0>) failed to connect: ** (DBConnection.ConnectionError) tcp connect (db:5432): connection refused - :econnrefused
api02-1  | 
api02-1  | 22:20:53.578 [error] Postgrex.Protocol (#PID<0.1326.0>) failed to connect: ** (DBConnection.ConnectionError) tcp connect (db:5432): connection refused - :econnrefused
api02-1  | 
api02-1  | 22:20:53.757 [error] Postgrex.Protocol (#PID<0.1307.0>) failed to connect: ** (DBConnection.ConnectionError) tcp connect (db:5432): connection refused - :econnrefused
api02-1  | 
api02-1  | 22:20:53.867 [error] Postgrex.Protocol (#PID<0.1313.0>) failed to connect: ** (DBConnection.ConnectionError) tcp connect (db:5432): connection refused - :econnrefused
api02-1  | 
api02-1  | 22:20:53.880 [error] Postgrex.Protocol (#PID<0.1329.0>) failed to connect: ** (DBConnection.ConnectionError) tcp connect (db:5432): connection refused - :econnrefused
api02-1  | 
api02-1  | 22:20:53.937 [error] Postgrex.Protocol (#PID<0.1328.0>) failed to connect: ** (DBConnection.ConnectionError) tcp connect (db:5432): connection refused - :econnrefused
api01-1  | 
api01-1  | 22:20:53.972 [error] Could not create schema migrations table. This error usually happens due to the following:
api01-1  | 
api01-1  |   * The database does not exist
api01-1  |   * The "schema_migrations" table, which Ecto uses for managing
api01-1  |     migrations, was defined by another library
api01-1  |   * There is a deadlock while migrating (such as using concurrent
api01-1  |     indexes with a migration_lock)
api01-1  | 
api01-1  | To fix the first issue, run "mix ecto.create" for the desired MIX_ENV.
api01-1  | 
api01-1  | To address the second, you can run "mix ecto.drop" followed by
api01-1  | "mix ecto.create", both for the desired MIX_ENV. Alternatively you may
api01-1  | configure Ecto to use another table and/or repository for managing
api01-1  | migrations:
api01-1  | 
api01-1  |     config :rinha_backend, RinhaBackend.Repo,
api01-1  |       migration_source: "some_other_table_for_schema_migrations",
api01-1  |       migration_repo: AnotherRepoForSchemaMigrations
api01-1  | 
api01-1  | The full error report is shown below.
api01-1  | 
api01-1  | 
api01-1  | 22:20:53.973 [notice] Application rinha_backend exited: exited in: RinhaBackend.Application.start(:normal, [])
api01-1  |     ** (EXIT) an exception was raised:
api01-1  |         ** (DBConnection.ConnectionError) connection not available and request was dropped from queue after 2000ms. This means requests are coming in and your connection pool cannot serve them fast enough. You can address this by:
api01-1  | 
api01-1  |   1. Ensuring your database is available and that you can connect to it
api01-1  |   2. Tracking down slow queries and making sure they are running fast enough
api01-1  |   3. Increasing the pool_size (although this increases resource consumption)
api01-1  |   4. Allowing requests to wait longer by increasing :queue_target and :queue_interval
api01-1  | 
api01-1  | See DBConnection.start_link/2 for more information
api01-1  | 
api01-1  |             (ecto_sql 3.11.1) lib/ecto/adapters/sql.ex:1054: Ecto.Adapters.SQL.raise_sql_call_error/1
api01-1  |             (elixir 1.16.1) lib/enum.ex:1700: Enum."-map/2-lists^map/1-1-"/2
api01-1  |             (ecto_sql 3.11.1) lib/ecto/adapters/sql.ex:1161: Ecto.Adapters.SQL.execute_ddl/4
api01-1  |             (ecto_sql 3.11.1) lib/ecto/migrator.ex:755: Ecto.Migrator.verbose_schema_migration/3
api01-1  |             (ecto_sql 3.11.1) lib/ecto/migrator.ex:563: Ecto.Migrator.lock_for_migrations/4
api01-1  |             (ecto_sql 3.11.1) lib/ecto/migrator.ex:432: Ecto.Migrator.run/4
api01-1  |             (ecto_sql 3.11.1) lib/ecto/migrator.ex:170: Ecto.Migrator.with_repo/3
api01-1  |             (rinha_backend 0.1.0) lib/rinha_backend/application.ex:36: anonymous fn/1 in RinhaBackend.Application.migrate/0
api02-1  | 
api02-1  | 22:20:54.157 [error] Postgrex.Protocol (#PID<0.1316.0>) failed to connect: ** (DBConnection.ConnectionError) tcp connect (db:5432): connection refused - :econnrefused
api02-1  | 
api02-1  | 22:20:54.301 [error] Postgrex.Protocol (#PID<0.1322.0>) failed to connect: ** (DBConnection.ConnectionError) tcp connect (db:5432): connection refused - :econnrefused
api02-1  | 
api02-1  | 22:20:54.359 [error] Postgrex.Protocol (#PID<0.1325.0>) failed to connect: ** (DBConnection.ConnectionError) tcp connect (db:5432): connection refused - :econnrefused
api02-1  | 
api02-1  | 22:20:54.384 [error] Postgrex.Protocol (#PID<0.1327.0>) failed to connect: ** (DBConnection.ConnectionError) tcp connect (db:5432): connection refused - :econnrefused
api02-1  | 
api02-1  | 22:20:54.564 [error] Postgrex.Protocol (#PID<0.1330.0>) failed to connect: ** (DBConnection.ConnectionError) tcp connect (db:5432): connection refused - :econnrefused
api02-1  | 
api02-1  | 22:20:54.633 [error] Postgrex.Protocol (#PID<0.1318.0>) failed to connect: ** (DBConnection.ConnectionError) tcp connect (db:5432): connection refused - :econnrefused
db-1     | performing post-bootstrap initialization ... ok
api02-1  | 
api02-1  | 22:20:54.739 [error] Postgrex.Protocol (#PID<0.1314.0>) failed to connect: ** (DBConnection.ConnectionError) tcp connect (db:5432): connection refused - :econnrefused
api02-1  | 
api02-1  | 22:20:54.765 [error] Postgrex.Protocol (#PID<0.1315.0>) failed to connect: ** (DBConnection.ConnectionError) tcp connect (db:5432): connection refused - :econnrefused
api02-1  | 
api02-1  | 22:20:54.816 [error] Postgrex.Protocol (#PID<0.1308.0>) failed to connect: ** (DBConnection.ConnectionError) tcp connect (db:5432): connection refused - :econnrefused
nginx-1  | 2024/02/14 01:20:54 [error] 29#29: *5 no live upstreams while connecting to upstream, client: 172.20.0.1, server: , request: "GET /clientes/1/extrato HTTP/1.1", upstream: "http://api/clientes/1/extrato", host: "localhost:9999"
api02-1  | 
api02-1  | 22:20:55.024 [error] Postgrex.Protocol (#PID<0.1323.0>) failed to connect: ** (DBConnection.ConnectionError) tcp connect (db:5432): connection refused - :econnrefused
db-1     | initdb: warning: enabling "trust" authentication for local connections
db-1     | initdb: hint: You can change this by editing pg_hba.conf or using the option -A, or --auth-local and --auth-host, the next time you run initdb.
db-1     | syncing data to disk ... ok
db-1     | 
db-1     | 
db-1     | Success. You can now start the database server using:
db-1     | 
db-1     |     pg_ctl -D /var/lib/postgresql/data -l logfile start
db-1     | 
api02-1  | 
api02-1  | 22:20:55.220 [error] Postgrex.Protocol (#PID<0.1324.0>) failed to connect: ** (DBConnection.ConnectionError) tcp connect (db:5432): connection refused - :econnrefused
db-1     | waiting for server to start....2024-02-14 01:20:55.315 UTC [37] LOG:  starting PostgreSQL 16.1 on x86_64-pc-linux-musl, compiled by gcc (Alpine 13.2.1_git20231014) 13.2.1 20231014, 64-bit
db-1     | 2024-02-14 01:20:55.318 UTC [37] LOG:  listening on Unix socket "/var/run/postgresql/.s.PGSQL.5432"
db-1     | 2024-02-14 01:20:55.327 UTC [40] LOG:  database system was shut down at 2024-02-14 01:20:54 UTC
db-1     | 2024-02-14 01:20:55.334 UTC [37] LOG:  database system is ready to accept connections
db-1     |  done
db-1     | server started
api01-1  | Kernel pid terminated (application_controller) ("{application_start_failure,rinha_backend,{bad_return,{{'Elixir.RinhaBackend.Application',start,[normal,[]]},{'EXIT',{#{message => <<\"connection not available and request was dropped from queue after 2000ms. This means requests are coming in and your connection pool cannot serve them fast enough. You can address this by:\n\n  1. Ensuring your database is available and that you can connect to it\n  2. Tracking down slow queries and making sure they are running fast enough\n  3. Increasing the pool_size (although this increases resource consumption)\n  4. Allowing requests to wait longer by increasing :queue_target and :queue_interval\n\nSee DBConnection.start_link/2 for more information\n\">>,reason => queue_timeout,'__struct__' => 'Elixir.DBConnection.ConnectionError','__exception__' => true,severity => error},[{'Elixir.Ecto.Adapters.SQL',raise_sql_call_error,1,[{file,\"lib/ecto/adapters/sql.ex\"},{line,1054},{error_info,#{module => 'Elixir.Exception'}}]},{'El
api01-1  | 
api01-1  | Crash dump is being written to: erl_crash.dump...done
db-1     | CREATE DATABASE
db-1     | 
db-1     | 
db-1     | /usr/local/bin/docker-entrypoint.sh: ignoring /docker-entrypoint-initdb.d/*
db-1     | 
db-1     | waiting for server to shut down...2024-02-14 01:20:55.794 UTC [37] LOG:  received fast shutdown request
db-1     | .2024-02-14 01:20:55.834 UTC [37] LOG:  aborting any active transactions
db-1     | 2024-02-14 01:20:55.842 UTC [37] LOG:  background worker "logical replication launcher" (PID 43) exited with exit code 1
db-1     | 2024-02-14 01:20:55.842 UTC [38] LOG:  shutting down
db-1     | 2024-02-14 01:20:55.844 UTC [38] LOG:  checkpoint starting: shutdown immediate
api02-1  | 
api02-1  | 22:20:55.963 [error] Postgrex.Protocol (#PID<0.1331.0>) failed to connect: ** (DBConnection.ConnectionError) tcp connect (db:5432): connection refused - :econnrefused
db-1     | 2024-02-14 01:20:56.088 UTC [38] LOG:  checkpoint complete: wrote 925 buffers (5.6%); 0 WAL file(s) added, 0 removed, 0 recycled; write=0.166 s, sync=0.064 s, total=0.246 s; sync files=301, longest=0.023 s, average=0.001 s; distance=4268 kB, estimate=4268 kB; lsn=0/191B6B0, redo lsn=0/191B6B0
db-1     | 2024-02-14 01:20:56.100 UTC [37] LOG:  database system is shut down
db-1     |  done
db-1     | server stopped
db-1     | 
db-1     | PostgreSQL init process complete; ready for start up.
db-1     | 
db-1     | 2024-02-14 01:20:56.302 UTC [1] LOG:  starting PostgreSQL 16.1 on x86_64-pc-linux-musl, compiled by gcc (Alpine 13.2.1_git20231014) 13.2.1 20231014, 64-bit
db-1     | 2024-02-14 01:20:56.302 UTC [1] LOG:  listening on IPv4 address "0.0.0.0", port 5432
db-1     | 2024-02-14 01:20:56.302 UTC [1] LOG:  listening on IPv6 address "::", port 5432
db-1     | 2024-02-14 01:20:56.377 UTC [1] LOG:  listening on Unix socket "/var/run/postgresql/.s.PGSQL.5432"
db-1     | 2024-02-14 01:20:56.400 UTC [53] LOG:  database system was shut down at 2024-02-14 01:20:56 UTC
api01-1 exited with code 1
db-1     | 2024-02-14 01:20:56.410 UTC [1] LOG:  database system is ready to accept connections
nginx-1  | 2024/02/14 01:20:56 [error] 29#29: *6 no live upstreams while connecting to upstream, client: 172.20.0.1, server: , request: "GET /clientes/1/extrato HTTP/1.1", upstream: "http://api/clientes/1/extrato", host: "localhost:9999"
nginx-1  | 2024/02/14 01:20:58 [error] 29#29: *7 no live upstreams while connecting to upstream, client: 172.20.0.1, server: , request: "GET /clientes/1/extrato HTTP/1.1", upstream: "http://api/clientes/1/extrato", host: "localhost:9999"
nginx-1  | 2024/02/14 01:21:00 [error] 29#29: *8 no live upstreams while connecting to upstream, client: 172.20.0.1, server: , request: "GET /clientes/1/extrato HTTP/1.1", upstream: "http://api/clientes/1/extrato", host: "localhost:9999"
db-1     | 2024-02-14 01:21:02.909 UTC [61] ERROR:  relation "clients" does not exist at character 54
db-1     | 2024-02-14 01:21:02.909 UTC [61] STATEMENT:  SELECT c0."id", c0."credit_limit", c0."balance" FROM "clients" AS c0 WHERE (c0."id" = $1)
api02-1  | 
api02-1  | 22:21:02.910 [error] #PID<0.1443.0> running RinhaBackend.Router (connection #PID<0.1442.0>, stream id 1) terminated
api02-1  | Server: api:80 (http)
api02-1  | Request: GET /clientes/1/extrato
api02-1  | ** (exit) an exception was raised:
api02-1  |     ** (Postgrex.Error) ERROR 42P01 (undefined_table) relation "clients" does not exist
api02-1  | 
api02-1  |     query: SELECT c0."id", c0."credit_limit", c0."balance" FROM "clients" AS c0 WHERE (c0."id" = $1)
api02-1  |         (ecto_sql 3.11.1) lib/ecto/adapters/sql.ex:1054: Ecto.Adapters.SQL.raise_sql_call_error/1
api02-1  |         (ecto_sql 3.11.1) lib/ecto/adapters/sql.ex:952: Ecto.Adapters.SQL.execute/6
api02-1  |         (ecto 3.11.1) lib/ecto/repo/queryable.ex:232: Ecto.Repo.Queryable.execute/4
api02-1  |         (ecto 3.11.1) lib/ecto/repo/queryable.ex:19: Ecto.Repo.Queryable.all/3
api02-1  |         (ecto 3.11.1) lib/ecto/repo/queryable.ex:154: Ecto.Repo.Queryable.one/3
api02-1  |         (rinha_backend 0.1.0) lib/rinha_backend/commands/generate_statement.ex:37: RinhaBackend.Commands.GenerateStatement.do_execute/1
api02-1  |         (rinha_backend 0.1.0) lib/rinha_backend/controllers/clientes_controller.ex:30: RinhaBackend.Controllers.ClientsController.get_statement/1
api02-1  |         (rinha_backend 0.1.0) lib/rinha_backend/router.ex:20: anonymous fn/2 in RinhaBackend.Router.do_match/4
db-1     | 2024-02-14 01:21:04.920 UTC [62] ERROR:  relation "clients" does not exist at character 54
db-1     | 2024-02-14 01:21:04.920 UTC [62] STATEMENT:  SELECT c0."id", c0."credit_limit", c0."balance" FROM "clients" AS c0 WHERE (c0."id" = $1)
api02-1  | 
api02-1  | 22:21:04.921 [error] #PID<0.1445.0> running RinhaBackend.Router (connection #PID<0.1444.0>, stream id 1) terminated
api02-1  | Server: api:80 (http)
api02-1  | Request: GET /clientes/1/extrato
api02-1  | ** (exit) an exception was raised:
api02-1  |     ** (Postgrex.Error) ERROR 42P01 (undefined_table) relation "clients" does not exist
api02-1  | 
api02-1  |     query: SELECT c0."id", c0."credit_limit", c0."balance" FROM "clients" AS c0 WHERE (c0."id" = $1)
api02-1  |         (ecto_sql 3.11.1) lib/ecto/adapters/sql.ex:1054: Ecto.Adapters.SQL.raise_sql_call_error/1
api02-1  |         (ecto_sql 3.11.1) lib/ecto/adapters/sql.ex:952: Ecto.Adapters.SQL.execute/6
api02-1  |         (ecto 3.11.1) lib/ecto/repo/queryable.ex:232: Ecto.Repo.Queryable.execute/4
api02-1  |         (ecto 3.11.1) lib/ecto/repo/queryable.ex:19: Ecto.Repo.Queryable.all/3
api02-1  |         (ecto 3.11.1) lib/ecto/repo/queryable.ex:154: Ecto.Repo.Queryable.one/3
api02-1  |         (rinha_backend 0.1.0) lib/rinha_backend/commands/generate_statement.ex:37: RinhaBackend.Commands.GenerateStatement.do_execute/1
api02-1  |         (rinha_backend 0.1.0) lib/rinha_backend/controllers/clientes_controller.ex:30: RinhaBackend.Controllers.ClientsController.get_statement/1
api02-1  |         (rinha_backend 0.1.0) lib/rinha_backend/router.ex:20: anonymous fn/2 in RinhaBackend.Router.do_match/4
nginx-1  | 2024/02/14 01:22:06 [error] 29#29: *13 upstream timed out (110: Connection timed out) while connecting to upstream, client: 172.20.0.1, server: , request: "GET /clientes/1/extrato HTTP/1.1", upstream: "http://172.20.0.4:4001/clientes/1/extrato", host: "localhost:9999"
db-1     | 2024-02-14 01:22:06.993 UTC [59] ERROR:  relation "clients" does not exist at character 54
db-1     | 2024-02-14 01:22:06.993 UTC [59] STATEMENT:  SELECT c0."id", c0."credit_limit", c0."balance" FROM "clients" AS c0 WHERE (c0."id" = $1)
api02-1  | 
api02-1  | 22:22:06.993 [error] #PID<0.1447.0> running RinhaBackend.Router (connection #PID<0.1446.0>, stream id 1) terminated
api02-1  | Server: api:80 (http)
api02-1  | Request: GET /clientes/1/extrato
api02-1  | ** (exit) an exception was raised:
api02-1  |     ** (Postgrex.Error) ERROR 42P01 (undefined_table) relation "clients" does not exist
api02-1  | 
api02-1  |     query: SELECT c0."id", c0."credit_limit", c0."balance" FROM "clients" AS c0 WHERE (c0."id" = $1)
api02-1  |         (ecto_sql 3.11.1) lib/ecto/adapters/sql.ex:1054: Ecto.Adapters.SQL.raise_sql_call_error/1
api02-1  |         (ecto_sql 3.11.1) lib/ecto/adapters/sql.ex:952: Ecto.Adapters.SQL.execute/6
api02-1  |         (ecto 3.11.1) lib/ecto/repo/queryable.ex:232: Ecto.Repo.Queryable.execute/4
api02-1  |         (ecto 3.11.1) lib/ecto/repo/queryable.ex:19: Ecto.Repo.Queryable.all/3
api02-1  |         (ecto 3.11.1) lib/ecto/repo/queryable.ex:154: Ecto.Repo.Queryable.one/3
api02-1  |         (rinha_backend 0.1.0) lib/rinha_backend/commands/generate_statement.ex:37: RinhaBackend.Commands.GenerateStatement.do_execute/1
api02-1  |         (rinha_backend 0.1.0) lib/rinha_backend/controllers/clientes_controller.ex:30: RinhaBackend.Controllers.ClientsController.get_statement/1
api02-1  |         (rinha_backend 0.1.0) lib/rinha_backend/router.ex:20: anonymous fn/2 in RinhaBackend.Router.do_match/4
db-1     | 2024-02-14 01:22:09.004 UTC [62] ERROR:  relation "clients" does not exist at character 54
db-1     | 2024-02-14 01:22:09.004 UTC [62] STATEMENT:  SELECT c0."id", c0."credit_limit", c0."balance" FROM "clients" AS c0 WHERE (c0."id" = $1)
api02-1  | 
api02-1  | 22:22:09.005 [error] #PID<0.1449.0> running RinhaBackend.Router (connection #PID<0.1448.0>, stream id 1) terminated
api02-1  | Server: api:80 (http)
api02-1  | Request: GET /clientes/1/extrato
api02-1  | ** (exit) an exception was raised:
api02-1  |     ** (Postgrex.Error) ERROR 42P01 (undefined_table) relation "clients" does not exist
api02-1  | 
api02-1  |     query: SELECT c0."id", c0."credit_limit", c0."balance" FROM "clients" AS c0 WHERE (c0."id" = $1)
api02-1  |         (ecto_sql 3.11.1) lib/ecto/adapters/sql.ex:1054: Ecto.Adapters.SQL.raise_sql_call_error/1
api02-1  |         (ecto_sql 3.11.1) lib/ecto/adapters/sql.ex:952: Ecto.Adapters.SQL.execute/6
api02-1  |         (ecto 3.11.1) lib/ecto/repo/queryable.ex:232: Ecto.Repo.Queryable.execute/4
api02-1  |         (ecto 3.11.1) lib/ecto/repo/queryable.ex:19: Ecto.Repo.Queryable.all/3
api02-1  |         (ecto 3.11.1) lib/ecto/repo/queryable.ex:154: Ecto.Repo.Queryable.one/3
api02-1  |         (rinha_backend 0.1.0) lib/rinha_backend/commands/generate_statement.ex:37: RinhaBackend.Commands.GenerateStatement.do_execute/1
api02-1  |         (rinha_backend 0.1.0) lib/rinha_backend/controllers/clientes_controller.ex:30: RinhaBackend.Controllers.ClientsController.get_statement/1
api02-1  |         (rinha_backend 0.1.0) lib/rinha_backend/router.ex:20: anonymous fn/2 in RinhaBackend.Router.do_match/4
db-1     | 2024-02-14 01:22:11.015 UTC [69] ERROR:  relation "clients" does not exist at character 54
db-1     | 2024-02-14 01:22:11.015 UTC [69] STATEMENT:  SELECT c0."id", c0."credit_limit", c0."balance" FROM "clients" AS c0 WHERE (c0."id" = $1)
api02-1  | 
api02-1  | 22:22:11.016 [error] #PID<0.1451.0> running RinhaBackend.Router (connection #PID<0.1450.0>, stream id 1) terminated
api02-1  | Server: api:80 (http)
api02-1  | Request: GET /clientes/1/extrato
api02-1  | ** (exit) an exception was raised:
api02-1  |     ** (Postgrex.Error) ERROR 42P01 (undefined_table) relation "clients" does not exist
api02-1  | 
api02-1  |     query: SELECT c0."id", c0."credit_limit", c0."balance" FROM "clients" AS c0 WHERE (c0."id" = $1)
api02-1  |         (ecto_sql 3.11.1) lib/ecto/adapters/sql.ex:1054: Ecto.Adapters.SQL.raise_sql_call_error/1
api02-1  |         (ecto_sql 3.11.1) lib/ecto/adapters/sql.ex:952: Ecto.Adapters.SQL.execute/6
api02-1  |         (ecto 3.11.1) lib/ecto/repo/queryable.ex:232: Ecto.Repo.Queryable.execute/4
api02-1  |         (ecto 3.11.1) lib/ecto/repo/queryable.ex:19: Ecto.Repo.Queryable.all/3
api02-1  |         (ecto 3.11.1) lib/ecto/repo/queryable.ex:154: Ecto.Repo.Queryable.one/3
api02-1  |         (rinha_backend 0.1.0) lib/rinha_backend/commands/generate_statement.ex:37: RinhaBackend.Commands.GenerateStatement.do_execute/1
api02-1  |         (rinha_backend 0.1.0) lib/rinha_backend/controllers/clientes_controller.ex:30: RinhaBackend.Controllers.ClientsController.get_statement/1
api02-1  |         (rinha_backend 0.1.0) lib/rinha_backend/router.ex:20: anonymous fn/2 in RinhaBackend.Router.do_match/4
db-1     | 2024-02-14 01:22:13.027 UTC [61] ERROR:  relation "clients" does not exist at character 54
db-1     | 2024-02-14 01:22:13.027 UTC [61] STATEMENT:  SELECT c0."id", c0."credit_limit", c0."balance" FROM "clients" AS c0 WHERE (c0."id" = $1)
api02-1  | 
api02-1  | 22:22:13.027 [error] #PID<0.1453.0> running RinhaBackend.Router (connection #PID<0.1452.0>, stream id 1) terminated
api02-1  | Server: api:80 (http)
api02-1  | Request: GET /clientes/1/extrato
api02-1  | ** (exit) an exception was raised:
api02-1  |     ** (Postgrex.Error) ERROR 42P01 (undefined_table) relation "clients" does not exist
api02-1  | 
api02-1  |     query: SELECT c0."id", c0."credit_limit", c0."balance" FROM "clients" AS c0 WHERE (c0."id" = $1)
api02-1  |         (ecto_sql 3.11.1) lib/ecto/adapters/sql.ex:1054: Ecto.Adapters.SQL.raise_sql_call_error/1
api02-1  |         (ecto_sql 3.11.1) lib/ecto/adapters/sql.ex:952: Ecto.Adapters.SQL.execute/6
api02-1  |         (ecto 3.11.1) lib/ecto/repo/queryable.ex:232: Ecto.Repo.Queryable.execute/4
api02-1  |         (ecto 3.11.1) lib/ecto/repo/queryable.ex:19: Ecto.Repo.Queryable.all/3
api02-1  |         (ecto 3.11.1) lib/ecto/repo/queryable.ex:154: Ecto.Repo.Queryable.one/3
api02-1  |         (rinha_backend 0.1.0) lib/rinha_backend/commands/generate_statement.ex:37: RinhaBackend.Commands.GenerateStatement.do_execute/1
api02-1  |         (rinha_backend 0.1.0) lib/rinha_backend/controllers/clientes_controller.ex:30: RinhaBackend.Controllers.ClientsController.get_statement/1
api02-1  |         (rinha_backend 0.1.0) lib/rinha_backend/router.ex:20: anonymous fn/2 in RinhaBackend.Router.do_match/4
db-1     | 2024-02-14 01:22:15.038 UTC [67] ERROR:  relation "clients" does not exist at character 54
db-1     | 2024-02-14 01:22:15.038 UTC [67] STATEMENT:  SELECT c0."id", c0."credit_limit", c0."balance" FROM "clients" AS c0 WHERE (c0."id" = $1)
api02-1  | 
api02-1  | 22:22:15.039 [error] #PID<0.1455.0> running RinhaBackend.Router (connection #PID<0.1454.0>, stream id 1) terminated
api02-1  | Server: api:80 (http)
api02-1  | Request: GET /clientes/1/extrato
api02-1  | ** (exit) an exception was raised:
api02-1  |     ** (Postgrex.Error) ERROR 42P01 (undefined_table) relation "clients" does not exist
api02-1  | 
api02-1  |     query: SELECT c0."id", c0."credit_limit", c0."balance" FROM "clients" AS c0 WHERE (c0."id" = $1)
api02-1  |         (ecto_sql 3.11.1) lib/ecto/adapters/sql.ex:1054: Ecto.Adapters.SQL.raise_sql_call_error/1
api02-1  |         (ecto_sql 3.11.1) lib/ecto/adapters/sql.ex:952: Ecto.Adapters.SQL.execute/6
api02-1  |         (ecto 3.11.1) lib/ecto/repo/queryable.ex:232: Ecto.Repo.Queryable.execute/4
api02-1  |         (ecto 3.11.1) lib/ecto/repo/queryable.ex:19: Ecto.Repo.Queryable.all/3
api02-1  |         (ecto 3.11.1) lib/ecto/repo/queryable.ex:154: Ecto.Repo.Queryable.one/3
api02-1  |         (rinha_backend 0.1.0) lib/rinha_backend/commands/generate_statement.ex:37: RinhaBackend.Commands.GenerateStatement.do_execute/1
api02-1  |         (rinha_backend 0.1.0) lib/rinha_backend/controllers/clientes_controller.ex:30: RinhaBackend.Controllers.ClientsController.get_statement/1
api02-1  |         (rinha_backend 0.1.0) lib/rinha_backend/router.ex:20: anonymous fn/2 in RinhaBackend.Router.do_match/4
db-1     | 2024-02-14 01:22:17.050 UTC [63] ERROR:  relation "clients" does not exist at character 54
db-1     | 2024-02-14 01:22:17.050 UTC [63] STATEMENT:  SELECT c0."id", c0."credit_limit", c0."balance" FROM "clients" AS c0 WHERE (c0."id" = $1)
api02-1  | 
api02-1  | 22:22:17.050 [error] #PID<0.1457.0> running RinhaBackend.Router (connection #PID<0.1456.0>, stream id 1) terminated
api02-1  | Server: api:80 (http)
api02-1  | Request: GET /clientes/1/extrato
api02-1  | ** (exit) an exception was raised:
api02-1  |     ** (Postgrex.Error) ERROR 42P01 (undefined_table) relation "clients" does not exist
api02-1  | 
api02-1  |     query: SELECT c0."id", c0."credit_limit", c0."balance" FROM "clients" AS c0 WHERE (c0."id" = $1)
api02-1  |         (ecto_sql 3.11.1) lib/ecto/adapters/sql.ex:1054: Ecto.Adapters.SQL.raise_sql_call_error/1
api02-1  |         (ecto_sql 3.11.1) lib/ecto/adapters/sql.ex:952: Ecto.Adapters.SQL.execute/6
api02-1  |         (ecto 3.11.1) lib/ecto/repo/queryable.ex:232: Ecto.Repo.Queryable.execute/4
api02-1  |         (ecto 3.11.1) lib/ecto/repo/queryable.ex:19: Ecto.Repo.Queryable.all/3
api02-1  |         (ecto 3.11.1) lib/ecto/repo/queryable.ex:154: Ecto.Repo.Queryable.one/3
api02-1  |         (rinha_backend 0.1.0) lib/rinha_backend/commands/generate_statement.ex:37: RinhaBackend.Commands.GenerateStatement.do_execute/1
api02-1  |         (rinha_backend 0.1.0) lib/rinha_backend/controllers/clientes_controller.ex:30: RinhaBackend.Controllers.ClientsController.get_statement/1
api02-1  |         (rinha_backend 0.1.0) lib/rinha_backend/router.ex:20: anonymous fn/2 in RinhaBackend.Router.do_match/4
db-1     | 2024-02-14 01:22:19.062 UTC [64] ERROR:  relation "clients" does not exist at character 54
db-1     | 2024-02-14 01:22:19.062 UTC [64] STATEMENT:  SELECT c0."id", c0."credit_limit", c0."balance" FROM "clients" AS c0 WHERE (c0."id" = $1)
api02-1  | 
api02-1  | 22:22:19.062 [error] #PID<0.1459.0> running RinhaBackend.Router (connection #PID<0.1458.0>, stream id 1) terminated
api02-1  | Server: api:80 (http)
api02-1  | Request: GET /clientes/1/extrato
api02-1  | ** (exit) an exception was raised:
api02-1  |     ** (Postgrex.Error) ERROR 42P01 (undefined_table) relation "clients" does not exist
api02-1  | 
api02-1  |     query: SELECT c0."id", c0."credit_limit", c0."balance" FROM "clients" AS c0 WHERE (c0."id" = $1)
api02-1  |         (ecto_sql 3.11.1) lib/ecto/adapters/sql.ex:1054: Ecto.Adapters.SQL.raise_sql_call_error/1
api02-1  |         (ecto_sql 3.11.1) lib/ecto/adapters/sql.ex:952: Ecto.Adapters.SQL.execute/6
api02-1  |         (ecto 3.11.1) lib/ecto/repo/queryable.ex:232: Ecto.Repo.Queryable.execute/4
api02-1  |         (ecto 3.11.1) lib/ecto/repo/queryable.ex:19: Ecto.Repo.Queryable.all/3
api02-1  |         (ecto 3.11.1) lib/ecto/repo/queryable.ex:154: Ecto.Repo.Queryable.one/3
api02-1  |         (rinha_backend 0.1.0) lib/rinha_backend/commands/generate_statement.ex:37: RinhaBackend.Commands.GenerateStatement.do_execute/1
api02-1  |         (rinha_backend 0.1.0) lib/rinha_backend/controllers/clientes_controller.ex:30: RinhaBackend.Controllers.ClientsController.get_statement/1
api02-1  |         (rinha_backend 0.1.0) lib/rinha_backend/router.ex:20: anonymous fn/2 in RinhaBackend.Router.do_match/4
nginx-1  | 2024/02/14 01:22:24 [error] 29#29: *28 connect() failed (113: No route to host) while connecting to upstream, client: 172.20.0.1, server: , request: "GET /clientes/1/extrato HTTP/1.1", upstream: "http://172.20.0.4:4001/clientes/1/extrato", host: "localhost:9999"
db-1     | 2024-02-14 01:22:24.130 UTC [65] ERROR:  relation "clients" does not exist at character 54
db-1     | 2024-02-14 01:22:24.130 UTC [65] STATEMENT:  SELECT c0."id", c0."credit_limit", c0."balance" FROM "clients" AS c0 WHERE (c0."id" = $1)
api02-1  | 
api02-1  | 22:22:24.131 [error] #PID<0.1461.0> running RinhaBackend.Router (connection #PID<0.1460.0>, stream id 1) terminated
api02-1  | Server: api:80 (http)
api02-1  | Request: GET /clientes/1/extrato
api02-1  | ** (exit) an exception was raised:
api02-1  |     ** (Postgrex.Error) ERROR 42P01 (undefined_table) relation "clients" does not exist
api02-1  | 
api02-1  |     query: SELECT c0."id", c0."credit_limit", c0."balance" FROM "clients" AS c0 WHERE (c0."id" = $1)
api02-1  |         (ecto_sql 3.11.1) lib/ecto/adapters/sql.ex:1054: Ecto.Adapters.SQL.raise_sql_call_error/1
api02-1  |         (ecto_sql 3.11.1) lib/ecto/adapters/sql.ex:952: Ecto.Adapters.SQL.execute/6
api02-1  |         (ecto 3.11.1) lib/ecto/repo/queryable.ex:232: Ecto.Repo.Queryable.execute/4
api02-1  |         (ecto 3.11.1) lib/ecto/repo/queryable.ex:19: Ecto.Repo.Queryable.all/3
api02-1  |         (ecto 3.11.1) lib/ecto/repo/queryable.ex:154: Ecto.Repo.Queryable.one/3
api02-1  |         (rinha_backend 0.1.0) lib/rinha_backend/commands/generate_statement.ex:37: RinhaBackend.Commands.GenerateStatement.do_execute/1
api02-1  |         (rinha_backend 0.1.0) lib/rinha_backend/controllers/clientes_controller.ex:30: RinhaBackend.Controllers.ClientsController.get_statement/1
api02-1  |         (rinha_backend 0.1.0) lib/rinha_backend/router.ex:20: anonymous fn/2 in RinhaBackend.Router.do_match/4
db-1     | 2024-02-14 01:22:26.142 UTC [72] ERROR:  relation "clients" does not exist at character 54
db-1     | 2024-02-14 01:22:26.142 UTC [72] STATEMENT:  SELECT c0."id", c0."credit_limit", c0."balance" FROM "clients" AS c0 WHERE (c0."id" = $1)
api02-1  | 
api02-1  | 22:22:26.142 [error] #PID<0.1463.0> running RinhaBackend.Router (connection #PID<0.1462.0>, stream id 1) terminated
api02-1  | Server: api:80 (http)
api02-1  | Request: GET /clientes/1/extrato
api02-1  | ** (exit) an exception was raised:
api02-1  |     ** (Postgrex.Error) ERROR 42P01 (undefined_table) relation "clients" does not exist
api02-1  | 
api02-1  |     query: SELECT c0."id", c0."credit_limit", c0."balance" FROM "clients" AS c0 WHERE (c0."id" = $1)
api02-1  |         (ecto_sql 3.11.1) lib/ecto/adapters/sql.ex:1054: Ecto.Adapters.SQL.raise_sql_call_error/1
api02-1  |         (ecto_sql 3.11.1) lib/ecto/adapters/sql.ex:952: Ecto.Adapters.SQL.execute/6
api02-1  |         (ecto 3.11.1) lib/ecto/repo/queryable.ex:232: Ecto.Repo.Queryable.execute/4
api02-1  |         (ecto 3.11.1) lib/ecto/repo/queryable.ex:19: Ecto.Repo.Queryable.all/3
api02-1  |         (ecto 3.11.1) lib/ecto/repo/queryable.ex:154: Ecto.Repo.Queryable.one/3
api02-1  |         (rinha_backend 0.1.0) lib/rinha_backend/commands/generate_statement.ex:37: RinhaBackend.Commands.GenerateStatement.do_execute/1
api02-1  |         (rinha_backend 0.1.0) lib/rinha_backend/controllers/clientes_controller.ex:30: RinhaBackend.Controllers.ClientsController.get_statement/1
api02-1  |         (rinha_backend 0.1.0) lib/rinha_backend/router.ex:20: anonymous fn/2 in RinhaBackend.Router.do_match/4
db-1     | 2024-02-14 01:22:28.153 UTC [75] ERROR:  relation "clients" does not exist at character 54
db-1     | 2024-02-14 01:22:28.153 UTC [75] STATEMENT:  SELECT c0."id", c0."credit_limit", c0."balance" FROM "clients" AS c0 WHERE (c0."id" = $1)
api02-1  | 
api02-1  | 22:22:28.153 [error] #PID<0.1465.0> running RinhaBackend.Router (connection #PID<0.1464.0>, stream id 1) terminated
api02-1  | Server: api:80 (http)
api02-1  | Request: GET /clientes/1/extrato
api02-1  | ** (exit) an exception was raised:
api02-1  |     ** (Postgrex.Error) ERROR 42P01 (undefined_table) relation "clients" does not exist
api02-1  | 
api02-1  |     query: SELECT c0."id", c0."credit_limit", c0."balance" FROM "clients" AS c0 WHERE (c0."id" = $1)
api02-1  |         (ecto_sql 3.11.1) lib/ecto/adapters/sql.ex:1054: Ecto.Adapters.SQL.raise_sql_call_error/1
api02-1  |         (ecto_sql 3.11.1) lib/ecto/adapters/sql.ex:952: Ecto.Adapters.SQL.execute/6
api02-1  |         (ecto 3.11.1) lib/ecto/repo/queryable.ex:232: Ecto.Repo.Queryable.execute/4
api02-1  |         (ecto 3.11.1) lib/ecto/repo/queryable.ex:19: Ecto.Repo.Queryable.all/3
api02-1  |         (ecto 3.11.1) lib/ecto/repo/queryable.ex:154: Ecto.Repo.Queryable.one/3
api02-1  |         (rinha_backend 0.1.0) lib/rinha_backend/commands/generate_statement.ex:37: RinhaBackend.Commands.GenerateStatement.do_execute/1
api02-1  |         (rinha_backend 0.1.0) lib/rinha_backend/controllers/clientes_controller.ex:30: RinhaBackend.Controllers.ClientsController.get_statement/1
api02-1  |         (rinha_backend 0.1.0) lib/rinha_backend/router.ex:20: anonymous fn/2 in RinhaBackend.Router.do_match/4
db-1     | 2024-02-14 01:22:30.164 UTC [59] ERROR:  relation "clients" does not exist at character 54
db-1     | 2024-02-14 01:22:30.164 UTC [59] STATEMENT:  SELECT c0."id", c0."credit_limit", c0."balance" FROM "clients" AS c0 WHERE (c0."id" = $1)
api02-1  | 
api02-1  | 22:22:30.164 [error] #PID<0.1467.0> running RinhaBackend.Router (connection #PID<0.1466.0>, stream id 1) terminated
api02-1  | Server: api:80 (http)
api02-1  | Request: GET /clientes/1/extrato
api02-1  | ** (exit) an exception was raised:
api02-1  |     ** (Postgrex.Error) ERROR 42P01 (undefined_table) relation "clients" does not exist
api02-1  | 
api02-1  |     query: SELECT c0."id", c0."credit_limit", c0."balance" FROM "clients" AS c0 WHERE (c0."id" = $1)
api02-1  |         (ecto_sql 3.11.1) lib/ecto/adapters/sql.ex:1054: Ecto.Adapters.SQL.raise_sql_call_error/1
api02-1  |         (ecto_sql 3.11.1) lib/ecto/adapters/sql.ex:952: Ecto.Adapters.SQL.execute/6
api02-1  |         (ecto 3.11.1) lib/ecto/repo/queryable.ex:232: Ecto.Repo.Queryable.execute/4
api02-1  |         (ecto 3.11.1) lib/ecto/repo/queryable.ex:19: Ecto.Repo.Queryable.all/3
api02-1  |         (ecto 3.11.1) lib/ecto/repo/queryable.ex:154: Ecto.Repo.Queryable.one/3
api02-1  |         (rinha_backend 0.1.0) lib/rinha_backend/commands/generate_statement.ex:37: RinhaBackend.Commands.GenerateStatement.do_execute/1
api02-1  |         (rinha_backend 0.1.0) lib/rinha_backend/controllers/clientes_controller.ex:30: RinhaBackend.Controllers.ClientsController.get_statement/1
api02-1  |         (rinha_backend 0.1.0) lib/rinha_backend/router.ex:20: anonymous fn/2 in RinhaBackend.Router.do_match/4
db-1     | 2024-02-14 01:22:32.175 UTC [62] ERROR:  relation "clients" does not exist at character 54
db-1     | 2024-02-14 01:22:32.175 UTC [62] STATEMENT:  SELECT c0."id", c0."credit_limit", c0."balance" FROM "clients" AS c0 WHERE (c0."id" = $1)
api02-1  | 
api02-1  | 22:22:32.175 [error] #PID<0.1469.0> running RinhaBackend.Router (connection #PID<0.1468.0>, stream id 1) terminated
api02-1  | Server: api:80 (http)
api02-1  | Request: GET /clientes/1/extrato
api02-1  | ** (exit) an exception was raised:
api02-1  |     ** (Postgrex.Error) ERROR 42P01 (undefined_table) relation "clients" does not exist
api02-1  | 
api02-1  |     query: SELECT c0."id", c0."credit_limit", c0."balance" FROM "clients" AS c0 WHERE (c0."id" = $1)
api02-1  |         (ecto_sql 3.11.1) lib/ecto/adapters/sql.ex:1054: Ecto.Adapters.SQL.raise_sql_call_error/1
api02-1  |         (ecto_sql 3.11.1) lib/ecto/adapters/sql.ex:952: Ecto.Adapters.SQL.execute/6
api02-1  |         (ecto 3.11.1) lib/ecto/repo/queryable.ex:232: Ecto.Repo.Queryable.execute/4
api02-1  |         (ecto 3.11.1) lib/ecto/repo/queryable.ex:19: Ecto.Repo.Queryable.all/3
api02-1  |         (ecto 3.11.1) lib/ecto/repo/queryable.ex:154: Ecto.Repo.Queryable.one/3
api02-1  |         (rinha_backend 0.1.0) lib/rinha_backend/commands/generate_statement.ex:37: RinhaBackend.Commands.GenerateStatement.do_execute/1
api02-1  |         (rinha_backend 0.1.0) lib/rinha_backend/controllers/clientes_controller.ex:30: RinhaBackend.Controllers.ClientsController.get_statement/1
api02-1  |         (rinha_backend 0.1.0) lib/rinha_backend/router.ex:20: anonymous fn/2 in RinhaBackend.Router.do_match/4
nginx-1 exited with code 0
nginx-1 exited with code 0
api02-1 exited with code 0
api02-1 exited with code 143
db-1     | 2024-02-14 01:22:35.140 UTC [1] LOG:  received fast shutdown request
db-1     | 2024-02-14 01:22:35.142 UTC [1] LOG:  aborting any active transactions
db-1     | 2024-02-14 01:22:35.146 UTC [1] LOG:  background worker "logical replication launcher" (PID 56) exited with exit code 1
db-1     | 2024-02-14 01:22:35.147 UTC [51] LOG:  shutting down
db-1     | 2024-02-14 01:22:35.149 UTC [51] LOG:  checkpoint starting: shutdown immediate
db-1     | 2024-02-14 01:22:35.171 UTC [51] LOG:  checkpoint complete: wrote 38 buffers (0.2%); 0 WAL file(s) added, 0 removed, 0 recycled; write=0.009 s, sync=0.005 s, total=0.024 s; sync files=11, longest=0.003 s, average=0.001 s; distance=73 kB, estimate=73 kB; lsn=0/192DB90, redo lsn=0/192DB90
db-1     | 2024-02-14 01:22:35.179 UTC [1] LOG:  database system is shut down
db-1 exited with code 0
